Workbook

Sheet Sheet2
A1: ID | B1: 品种 | C1: 规格 | D1: 单位 | E1: 2023/1/4 | F1: 2023/1/11 | G1: 2023/1/18 | H1: 2023/2/1 | I1: 2023/2/8 | J1: 2023/2/15 | K1: 2023/2/22 | L1: 2023/3/1 | M1: 2023/3/8 | N1: 2023/3/15 | O1: 2023/3/22 | P1: 2023/3/29 | Q1: 2023/4/5 | R1: 2023/4/12 | S1: 2023/4/19 | T1: 2023/4/26 | U1: 2023/5/05 | V1: 2023/5/10 | W1: 2023/5/17 | X1: 2023/5/24 | Y1: 2023/5/31 | Z1: 2023/6/7 | AA1: 2023/6/14 | AB1: 2023/6/21 | AC1: 2023/6/28 | AD1: 45112 | AE1: 45120 | AF1: 45126 | AG1: 45133 | AH1: 45140 | AI1: 45147 | AJ1: 45154 | AK1: 45161 | AL1: 45168 | AM1: 45175 | AN1: 45182 | AO1: 45189 | AP1: 45196 | AQ1: 45210 | AR1: 45217 | AS1: 45224 | AT1: 45231 | AU1: 45238 | AV1: 45245 | AW1: 45252 | AX1: 45260 | AY1: 45266 | AZ1: 45273 | BA1: 45280 | BB1: 45287 | BC1: 45294 | BD1: 45301 | BE1: 45308 | BF1: 45315 | BG1: 45322 | BH1: 45329 | BI1: 45343 | BJ1: 45351 | BK1: 45357 | BL1: 45364 | BM1: 45371 | BN1: 45378 | BO1: 45385 | BP1: 45392 | BQ1: 45399 | BR1: 45406 | BS1: 45420 | BT1: 45427 | BU1: 45434 | BV1: 45441 | BW1: 45448 | BX1: 45455 | BY1: 45462 | BZ1: 45469 | CA1: 45476 | CB1: 45483 | CC1: 45490 | CD1: 45497 | CE1: 45504 | CF1: 45511 | CG1: 45518 | CH1: 45525 | CI1: 45532 | CJ1: 45539 | CK1: 45546 | CL1: 45549 | CM1: 45553 | CN1: 45560 | CO1: 45574 | CP1: 45581 | CQ1: 45588 | CR1: 45595 | CS1: 45602 | CT1: 45609 | CU1: 45616 | CV1: 45623 | CW1: 45630 | CX1: 45637 | CY1: 45644 | CZ1: 45651 | DA1: 45659 | DB1: 45665 | DC1: 45672 | DD1: 45679 | DE1: 45693 | DF1: 45700 | DG1: 45707 | DH1: 45714 | DI1: 45721 | DJ1: 45728 | DK1: 45735 | DL1: 45742 | DM1: 45743 | DN1: 45749 | DO1: 45756 | DP1: 45763 | DQ1: 45770 | DR1: 45777 | DS1: 45784 | DT1: 45791 | DU1: 45792 | DV1: 45798 | DW1: 45805 | DX1: 45812 | DY1: 45813 | DZ1: 45819 | EA1: 45826 | EB1: 45833 | EC1: 45840 | ED1: 45847 | EE1: 45854 | EF1: 45861 | EG1: 45868 | EH1: 45875 | EI1: 45882 | EJ1: 45889 | EK1: 45896 | EL1: 45903 | EM1: 45910 | EN1: 45917 | EO1: 45924 | EP1: 45939 | EQ1: 45945 | ER1: 45952 | ES1: 45959 | ET1: 45966 | EU1: 45973 | EV1: 45980 | EW1: 45987 | EX1: 45994 | EY1: 46001 | EZ1: 46008 | FA1: 46015 | FB1: 46022 | FC1: 46029 | FD1: 46036 | FE1: 46043 | FF1: 46050 | FG1: 46057 | FH1: 46064 | FI1: 46078 | FJ1: 46085 | FK1: 46092 | FL1: 46099 | FM1: 46106 | FN1: 46113 | FO1: 46120 | FP1: 46127 | FQ1: 46134 | FR1: 46141 | FS1: 46148 | FT1: 46155 | FU1: 46162 | FV1: 46169 | FW1: 46176 | FX1: 46183 | FY1: 46190 | FZ1: 46197 | GA1: 46204 | GB1: 46210 | GC1: 46218 | GD1: 46225 | GE1: 46232 | GF1: 46239 | GG1: 46246 | GH1: 46253 | GI1: 46260 | GJ1: 46267 | GK1: 46274 | GL1: 46281
A2: A2 | B2: 中国产复投多晶硅料9N | C2: 单晶用料-复投 | D2: 元/公斤 | E2: 210 | F2: 170 | G2: 170 | H2: 208 | I2: 240 | J2: 241 | K2: 241 | L2: 240 | M2: 228 | N2: 220 | O2: 215 | P2: 209 | Q2: 201 | R2: 196 | S2: 194 | T2: 182 | U2: 181 | V2: 161 | W2: 140 | X2: 135 | Y2: 120 | Z2: 115 | AA2: 65 | AB2: 64.8 | AC2: 64 | AD2: 64 | AE2: 64.5 | AF2: 66 | AG2: 68 | AH2: 70.5 | AI2: 71.5 | AJ2: 73.5 | AK2: 75 | AL2: 80 | AM2: 82 | AN2: 82 | AO2: 82 | AP2: 82 | AQ2: 82 | AR2: 80 | AS2: 75 | AT2: 70 | AU2: 65 | AV2: 63.5 | AW2: 63 | AX2: 63 | AY2: 62.5 | AZ2: 62.5 | BA2: 61 | BB2: 61 | BC2: 61 | BD2: 61 | BE2: 61.5 | BF2: 61.5 | BG2: 61.5 | BH2: 61.5 | BI2: 61.5 | BJ2: 61.5 | BK2: 61.5 | BL2: 61.5 | BM2: 61.5 | BN2: 60 | BO2: 60 | BP2: 58 | BQ2: 55 | BR2: 48 | BS2: 39 | BT2: 38 | BU2: 38 | BV2: 37 | BW2: 37 | BX2: 37 | BY2: 35 | BZ2: 35 | CA2: 35 | CB2: 35 | CC2: 35 | CD2: 35 | CE2: 35 | CF2: 35 | CG2: 35 | CH2: 35 | CI2: 35 | CJ2: 35 | CK2: 35 | CL2: 35 | CM2: 35 | CN2: 35 | CO2: 35 | CP2: 35 | CQ2: 35 | CR2: 35 | CS2: 35 | CT2: 35 | CU2: 35 | CV2: 35 | CW2: 35 | CX2: 35 | CY2: 35 | CZ2: 35 | DA2: 35 | DB2: 35 | DC2: 35 | DD2: 35 | DE2: 35 | DF2: 35 | DG2: 35 | DH2: 35 | DI2: 35 | DJ2: 35 | DK2: 35 | DL2: 35 | DM2: 35 | DN2: 35 | DO2: 35 | DP2: 35 | DQ2: 35 | DR2: 35 | DS2: 35 | DT2: 35 | DU2: 35 | DV2: 35 | DW2: 35 | DX2: 35 | DY2: 35 | DZ2: 35 | EA2: 33.5 | EB2: 33.5 | EC2: 33.5 | ED2: 33.5 | EE2: 43 | EF2: 43 | EG2: 43 | EH2: 43 | EI2: 43 | EJ2: 43 | EK2: 43.5 | EL2: 43.5 | EM2: 43.5 | EN2: 43.5 | EO2: 43.5 | EP2: 43.5 | EQ2: 43.5 | ER2: 43.5 | ES2: 43.5 | ET2: 43.5 | EU2: 43.5 | EV2: 43.5 | EW2: 43.5 | EX2: 43.5 | EY2: 43.5 | EZ2: 43.5 | FA2: 43.5 | FB2: 43.5 | FC2: 43.5 | FD2: 43.5 | FE2: 43.5 | FF2: 43.5 | FG2: 43.5 | FH2: 43.5 | FI2: 43.5 | FJ2: 43 | FK2: 43 | FL2: 42.5 | FM2: 42.5 | FN2: 36 | FO2: 34 | FP2: 34 | FQ2: 34 | FR2: 34 | FS2: 34 | FT2: 34 | FU2: 33.5 | FV2: 33.5 | FW2: 33.5 | FX2: 32 | FY2: 32 | FZ2: 31 | GA2: 31 | GB2: 31 | GC2: 31 | GD2: 31 | GE2: 30 | GF2: 30 | GG2: 30 | GH2: 30 | GI2: 30 | GJ2: 30 | GK2: 38 | GL2: 38
A3: A4 | B3: 中国产致密多晶硅料9N | C3: 单晶用料-致密 | D3: 元/公斤 | E3: 200 | F3: 162 | G3: 162 | H3: 200 | I3: 237 | J3: 237 | K3: 237 | L3: 234 | M3: 223 | N3: 218 | O3: 212 | P3: 206 | Q3: 199 | R3: 194 | S3: 192 | T3: 180 | U3: 178 | V3: 155 | W3: 138 | X3: 132 | Y3: 115 | Z3: 110 | AA3: 63 | AB3: 62.5 | AC3: 62 | AD3: 62 | AE3: 62 | AF3: 64 | AG3: 65 | AH3: 68 | AI3: 69 | AJ3: 71.5 | AK3: 73 | AL3: 77 | AM3: 77 | AN3: 77 | AO3: 77 | AP3: 77 | AQ3: 77 | AR3: 77 | AS3: 72 | AT3: 65 | AU3: 65 | AV3: 65 | AW3: 65 | AX3: 64 | AY3: 60 | AZ3: 60 | BA3: 59.5 | BB3: 59.5 | BC3: 59.5 | BD3: 59.5 | BE3: 59.5 | BF3: 59.5 | BG3: 59.5 | BH3: 59.5 | BI3: 59.5 | BJ3: 59.5 | BK3: 59.5 | BL3: 59.5 | BM3: 59.5 | BN3: 58 | BO3: 58 | BP3: 55 | BQ3: 52 | BR3: 46 | BS3: 38 | BT3: 37 | BU3: 37 | BV3: 36 | BW3: 36 | BX3: 36 | BY3: 34 | BZ3: 34 | CA3: 34 | CB3: 34 | CC3: 34 | CD3: 34 | CE3: 34 | CF3: 34 | CG3: 34 | CH3: 34 | CI3: 34 | CJ3: 34 | CK3: 34 | CL3: 34 | CM3: 34 | CN3: 34 | CO3: 34 | CP3: 34 | CQ3: 34 | CR3: 34 | CS3: 34 | CT3: 34 | CU3: 34 | CV3: 34 | CW3: 34 | CX3: 34 | CY3: 34 | CZ3: 34 | DA3: 34 | DB3: 34 | DC3: 34 | DD3: 34 | DE3: 34 | DF3: 34 | DG3: 34 | DH3: 34 | DI3: 34 | DJ3: 34 | DK3: 34 | DL3: 34 | DM3: 34 | DN3: 34 | DO3: 34 | DP3: 34 | DQ3: 34 | DR3: 34 | DS3: 34 | DT3: 34 | DU3: 34 | DV3: 34 | DW3: 34 | DX3: 34 | DY3: 34 | DZ3: 34 | EA3: 32.5 | EB3: 32.5 | EC3: 32.5 | ED3: 32.5 | EE3: 42 | EF3: 42 | EG3: 42 | EH3: 42 | EI3: 42 | EJ3: 42 | EK3: 42.5 | EL3: 42.5 | EM3: 42.5 | EN3: 42.5 | EO3: 42.5 | EP3: 42.5 | EQ3: 42.5 | ER3: 42.5 | ES3: 42.5 | ET3: 42.5 | EU3: 42.5 | EV3: 42.5 | EW3: 42.5 | EX3: 42.5 | EY3: 42.5 | EZ3: 42.5 | FA3: 42.5 | FB3: 42.5 | FC3: 42.5 | FD3: 42.5 | FE3: 42.5 | FF3: 42.5 | FG3: 42.5 | FH3: 42.5 | FI3: 42.5 | FJ3: 42 | FK3: 42 | FL3: 39.9 | FM3: 39.9 | FN3: 35.5 | FO3: 33 | FP3: 33 | FQ3: 33 | FR3: 33 | FS3: 33 | FT3: 33 | FU3: 33 | FV3: 32 | FW3: 32 | FX3: 31 | FY3: 31 | FZ3: 30 | GA3: 30 | GB3: 30 | GC3: 30 | GD3: 30 | GE3: 28 | GF3: 28 | GG3: 28 | GH3: 28 | GI3: 28 | GJ3: 28 | GK3: 36 | GL3: 36
A4: A1 | B4: 中国产多晶硅料8N | C4: 多晶用料 | D4: 元/公斤
A5: A3 | B5: 全球多晶硅料 | C5: — | D5: 美元/公斤 | E5: 30 | F5: 28 | G5: 28 | H5: 28 | I5: 35 | J5: 35 | K5: 35 | L5: 35 | M5: 33 | N5: 33 | O5: 33 | P5: 33 | Q5: 31 | R5: 30 | S5: 29 | T5: 27 | U5: 26 | V5: 23.5 | W5: 23 | X5: 22.8 | Y5: 21.5 | Z5: 21 | AA5: 20 | AB5: 20 | AC5: 20 | AD5: 20 | AE5: 20 | AF5: 20 | AG5: 20 | AH5: 20 | AI5: 20 | AJ5: 20 | AK5: 20 | AL5: 20 | AM5: 20 | AN5: 20 | AO5: 20 | AP5: 20 | AQ5: 20 | AR5: 20 | AS5: 20 | AT5: 20 | AU5: 20 | AV5: 20 | AW5: 20 | AX5: 20 | AY5: 20 | AZ5: 20 | BA5: 20 | BB5: 20 | BC5: 20 | BD5: 20 | BE5: 20 | BF5: 20 | BG5: 20 | BH5: 20 | BI5: 20 | BJ5: 20 | BK5: 20 | BL5: 20 | BM5: 20 | BN5: 20 | BO5: 20 | BP5: 20 | BQ5: 20 | BR5: 20 | BS5: 20 | BT5: 20 | BU5: 20 | BV5: 20 | BW5: 20 | BX5: 20 | BY5: 20 | BZ5: 20 | CA5: 20 | CB5: 20 | CC5: 20 | CD5: 20 | CE5: 20 | CF5: 20 | CG5: 20 | CH5: 20 | CI5: 20 | CJ5: 20 | CK5: 20 | CL5: 20 | CM5: 20 | CN5: 20 | CO5: 20 | CP5: 20 | CQ5: 20 | CR5: 20 | CS5: 20 | CT5: 20 | CU5: 20 | CV5: 20 | CW5: 20 | CX5: 20 | CY5: 20 | CZ5: 20 | DA5: 20 | DB5: 20 | DC5: 20 | DD5: 20 | DE5: 20 | DF5: 20 | DG5: 20 | DH5: 20 | DI5: 20 | DJ5: 20 | DK5: 20 | DL5: 20 | DM5: 20 | DN5: 20 | DO5: 20 | DP5: 20 | DQ5: 20 | DR5: 20 | DS5: 20 | DT5: 20 | DU5: 20 | DV5: 20 | DW5: 20 | DX5: 20 | DY5: 20 | DZ5: 20 | EA5: 20 | EB5: 20 | EC5: 20 | ED5: 20 | EE5: 20 | EF5: 20 | EG5: 20 | EH5: 20 | EI5: 20 | EJ5: 20 | EK5: 20 | EL5: 20 | EM5: 20 | EN5: 20 | EO5: 20 | EP5: 20 | EQ5: 20 | ER5: 20 | ES5: 20 | ET5: 20 | EU5: 20 | EV5: 20 | EW5: 20 | EX5: 20 | EY5: 20 | EZ5: 20 | FA5: 20 | FB5: 20 | FC5: 20 | FD5: 20 | FE5: 20 | FF5: 20 | FG5: 20 | FH5: 20 | FI5: 20 | FJ5: 20 | FK5: 20 | FL5: 20 | FM5: 20 | FN5: 20
A6: B7 | B6: 多晶硅片高效 | C6: 157mm x 157mm | D6: 元/片
A7: B6 | B7: 多晶硅片中效 | C7: 157mm x 157mm | D7: 元/片
A8: B2 | B8: 单晶硅片（170um） | C8: 158.75mm x 158.75mm | D8: 元/片
A9: B3 | B9: 166mm单晶硅片（170um） | C9: 166mm x 166mm（170um） | D9: 元/片
A10: B3 | B10: 166mm单晶硅片（165um）（New！） | C10: 166mm x 166mm（165um） | D10: 元/片
A11: B3 | B11: 166mm单晶硅片（155um）（New！） | C11: 166mm x 166mm（155um）
A12: B11 | B12: 166mm单晶硅片（160um） | C12: 166mm x 166mm（160um） | D12: 元/片
A13: B14 | B13: 166mm单晶硅片（150um） | C13: 166mm x 166mm（150um） | D13: 元/片 | E13: 3.8 | F13: 3.8 | G13: 4.4 | H13: 4.6
A14: B4 | B14: 单晶硅片(170um) | C14: 182mm*182mm（170 um） | D14: 元/片
A15: B9 | B15: 182mm单晶硅片（New！） | C15: 182mm*182mm 单晶硅片（165 um） | D15: 元/片
A16: B9 | B16: 182mm单晶硅片(160um） | C16: 182mm*182mm 单晶硅片（160 um） | D16: 元/片
A17: B9 | B17: 182mm单晶硅片(155um） | C17: 182mm*182mm 单晶硅片（155 um）
A18: B15 | B18: 182mm单晶硅片(150um) | C18: 182mm*182mm（150 um） | D18: 元/片 | E18: 3.5 | F18: 3.6 | G18: 4.5 | H18: 4.8 | I18: 6.22 | J18: 6.22 | K18: 6.22 | L18: 6.22 | M18: 6.4 | N18: 6.5 | O18: 6.4 | P18: 6.4 | Q18: 6.4 | R18: 6.4 | S18: 6.38 | T18: 6.3 | U18: 5.84 | V18: 5.4 | W18: 4.6 | X18: 4.4 | Y18: 4 | Z18: 3.6 | AA18: 2.8 | AB18: 2.8 | AC18: 2.8 | AD18: 2.75 | AE18: 2.78 | AF18: 2.78 | AG18: 2.9 | AH18: 2.95 | AI18: 2.95 | AJ18: 3.15 | AK18: 3.35 | AL18: 3.35 | AM18: 3.35 | AN18: 3.35 | AO18: 3.35 | AP18: 3.08 | AQ18: 2.8 | AR18: 2.75 | AS18: 2.55 | AT18: 2.4 | AU18: 2.4 | AV18: 2.4 | AW18: 2.35 | AX18: 2.3 | AY18: 2.12 | AZ18: 2.12 | BA18: 2.05 | BB18: 2 | BC18: 2 | BD18: 2 | BE18: 2 | BF18: 2.02 | BG18: 2.02 | BH18: 2.02 | BI18: 2.02 | BJ18: 2.02 | BK18: 2.02 | BL18: 2 | BM18: 1.95 | BN18: 1.8 | BO18: 1.8 | BP18: 1.7 | BQ18: 1.7 | BR18: 1.67 | BS18: 1.55 | BT18: 1.45 | BU18: 1.25 | BV18: 1.25 | BW18: 1.25 | BX18: 1.25 | BY18: 1.25 | BZ18: 1.25 | CA18: 1.25 | CB18: 1.25 | CC18: 1.25 | CD18: 1.25 | CE18: 1.25 | CF18: 1.25 | CG18: 1.25 | CH18: 1.25 | CI18: 1.25 | CJ18: 1.25 | CK18: 1.25 | CL18: 1.15 | CM18: 1.15 | CN18: 1.15 | CO18: 1.15 | CP18: 1.15 | CQ18: 1.15 | CR18: 1.15 | CS18: 1.1 | CT18: 1.08 | CU18: 1.08 | CV18: 1.08 | CW18: 1.08 | CX18: 1.08 | CY18: 1.08 | CZ18: 1.08 | DA18: 1.08 | DB18: 1.08 | DC18: 1.08 | DD18: 1.08 | DE18: 1.08 | DF18: 1.08 | DG18: 1.08 | DH18: 1.08 | DI18: 1.08 | DJ18: 1.08 | DK18: 1.08 | DL18: 1.08 | DM18: 1.08
A19: B5 | B19: 单晶硅片 | C19: 210mm*210mm | D19: 元/片
A20: B10 | B20: 210mm单晶硅片（New！） | C20: 210mm*210mm 单晶硅片（165 um） | D20: 元/片
A21: B10 | B21: 210mm单晶硅片(160um) | C21: 210mm*210mm 单晶硅片（160 um） | D21: 元/片
A22: B10 | B22: 210mm单晶硅片(155um) | C22: 210mm*210mm 单晶硅片（155 um）
A23: B12 | B23: 210mm单晶硅片(150um) | C23: 210mm*210mm 单晶硅片（150 um） | D23: 元/片 | E23: 4.8 | F23: 4.8 | G23: 6.2 | H23: 6.2 | I23: 8.2 | J23: 8.2 | K23: 8.2 | L23: 8.2 | M23: 8.2 | N23: 8.2 | O23: 8.2 | P23: 8.2 | Q23: 8.05 | R23: 8.05 | S23: 8.05 | T23: 8.05 | U23: 7.6 | V23: 7.4 | W23: 6 | X23: 5.8 | Y23: 5.1 | Z23: 5 | AA23: 4 | AB23: 4 | AC23: 4 | AD23: 4 | AE23: 3.77 | AF23: 3.77 | AG23: 3.77 | AH23: 3.92 | AI23: 3.92 | AJ23: 4.1 | AK23: 4.35 | AL23: 4.35 | AM23: 4.35 | AN23: 4.25 | AO23: 4.2 | AP23: 4.02 | AQ23: 3.9 | AR23: 3.66 | AS23: 3.45 | AT23: 3.3 | AU23: 3.3 | AV23: 3.3 | AW23: 3.3 | AX23: 3.3 | AY23: 3.3 | AZ23: 3.05 | BA23: 3 | BB23: 3 | BC23: 3 | BD23: 3 | BE23: 2.95 | BF23: 2.95 | BG23: 2.85 | BH23: 2.8 | BI23: 2.8 | BJ23: 2.8 | BK23: 2.8 | BL23: 2.75 | BM23: 2.75 | BN23: 2.4 | BO23: 2.4 | BP23: 2.35 | BQ23: 2.35 | BR23: 2.15 | BS23: 2.13 | BT23: 1.95 | BU23: 1.85 | BV23: 1.85 | BW23: 1.85 | BX23: 1.85 | BY23: 1.85 | BZ23: 1.85 | CA23: 1.85 | CB23: 1.85 | CC23: 1.85 | CD23: 1.85 | CE23: 1.85 | CF23: 1.85 | CG23: 1.85 | CH23: 1.85 | CI23: 1.85 | CJ23: 1.85 | CK23: 1.85 | CL23: 1.75 | CM23: 1.7 | CN23: 1.72 | CO23: 1.72 | CP23: 1.72 | CQ23: 1.72 | CR23: 1.72 | CS23: 1.65 | CT23: 1.65 | CU23: 1.65 | CV23: 1.65 | CW23: 1.65 | CX23: 1.65 | CY23: 1.65 | CZ23: 1.65 | DA23: 1.65 | DB23: 1.65 | DC23: 1.65 | DD23: 1.65 | DE23: 1.65 | DF23: 1.65 | DG23: 1.65 | DH23: 1.65 | DI23: 1.65 | DJ23: 1.65 | DK23: 1.65 | DL23: 1.65 | DM23: 1.58
A24: B8 | B24: N型-166mm单晶硅片(150um） | C24: 166mm x 166mm | D24: 元/片
A25: B13 | B25: N型-210mm单晶硅片(150um)（New！） | C25: 210mm*210mm 单晶硅片（150 um） | D25: 元/片 | E25: 6.3 | F25: 5.1 | G25: 5.3 | H25: 5.3
A26: C12 | B26: 多晶电池片(＞18.8%) | C26: 156.75mm x 156.75mm | D26: 元/瓦
A27: C3 | B27: 单晶PERC电池片（21.7-22.1%) | C27: 158.75mm x 158.75mm | D27: 元/瓦
A28: C7 | B28: 双面单晶PERC电池片（＞21.9%) | C28: 166mm x 166mm | D28: 元/瓦 | E28: 0.8 | F28: 0.83 | G28: 0.91 | H28: 0.96
A29: C8 | B29: 双面单晶PERC电池片(＞22.3%) | C29: 182mm*182mm | D29: 元/瓦 | E29: 0.8 | F29: 0.83 | G29: 0.92 | H29: 0.97 | I29: 1.14 | J29: 1.14 | K29: 1.13 | L29: 1.09 | M29: 1.09 | N29: 1.1 | O29: 1.09 | P29: 1.1 | Q29: 1.1 | R29: 1.1 | S29: 1.1 | T29: 1.1 | U29: 1.09 | V29: 1.04 | W29: 1 | X29: 0.96 | Y29: 0.88 | Z29: 0.86 | AA29: 0.79 | AB29: 0.72 | AC29: 0.71 | AD29: 0.715 | AE29: 0.73 | AF29: 0.735 | AG29: 0.745 | AH29: 0.75 | AI29: 0.755 | AJ29: 0.76 | AK29: 0.76 | AL29: 0.76 | AM29: 0.76 | AN29: 0.75 | AO29: 0.71 | AP29: 0.65 | AQ29: 0.61 | AR29: 0.55 | AS29: 0.51 | AT29: 0.48 | AU29: 0.46 | AV29: 0.46 | AW29: 0.46 | AX29: 0.45 | AY29: 0.43 | AZ29: 0.425 | BA29: 0.39 | BB29: 0.36 | BC29: 0.36 | BD29: 0.39 | BE29: 0.39 | BF29: 0.39 | BG29: 0.39 | BH29: 0.39 | BI29: 0.39 | BJ29: 0.39 | BK29: 0.38 | BL29: 0.38 | BM29: 0.38 | BN29: 0.375 | BO29: 0.375 | BP29: 0.35 | BQ29: 0.35 | BR29: 0.34 | BS29: 0.34 | BT29: 0.34 | BU29: 0.31 | BV29: 0.31 | BW29: 0.31 | BX29: 0.31 | BY29: 0.31 | BZ29: 0.31 | CA29: 0.31 | CB29: 0.31 | CC29: 0.31 | CD29: 0.31 | CE29: 0.31 | CF29: 0.31 | CG29: 0.31 | CH29: 0.31 | CI29: 0.31 | CJ29: 0.31 | CK29: 0.31 | CL29: 0.31 | CM29: 0.3 | CN29: 0.28 | CO29: 0.28 | CP29: 0.28 | CQ29: 0.28 | CR29: 0.28 | CS29: 0.28 | CT29: 0.275 | CU29: 0.275 | CV29: 0.275 | CW29: 0.275 | CX29: 0.275 | CY29: 0.275 | CZ29: 0.275 | DA29: 0.275 | DB29: 0.275 | DC29: 0.275 | DD29: 0.275 | DE29: 0.275 | DF29: 0.275 | DG29: 0.275 | DH29: 0.275 | DI29: 0.275 | DJ29: 0.275 | DK29: 0.275 | DL29: 0.275 | DM29: 0.275 | DN29: 0.275 | DO29: 0.275 | DP29: 0.275 | DQ29: 0.275 | DR29: 0.275 | DS29: 0.275 | DT29: 0.27 | DU29: 0.27 | DV29: 0.27 | DW29: 0.27 | DX29: 0.27 | DY29: 0.27 | DZ29: 0.27 | EA29: 0.27 | EB29: 0.27
A30: C9 | B30: 双面单晶PERC电池片(＞22.4%) | C30: 210mm*210mm | D30: 元/瓦 | E30: 0.8 | F30: 0.83 | G30: 0.92 | H30: 0.97 | I30: 1.14 | J30: 1.14 | K30: 1.13 | L30: 1.1 | M30: 1.1 | N30: 1.1 | O30: 1.1 | P30: 1.13 | Q30: 1.13 | R30: 1.13 | S30: 1.13 | T30: 1.13 | U30: 1.13 | V30: 1.1 | W30: 1.06 | X30: 1.02 | Y30: 0.9 | Z30: 0.9 | AA30: 0.83 | AB30: 0.75 | AC30: 0.74 | AD30: 0.74 | AE30: 0.73 | AF30: 0.73 | AG30: 0.73 | AH30: 0.74 | AI30: 0.74 | AJ30: 0.74 | AK30: 0.74 | AL30: 0.74 | AM30: 0.74 | AN30: 0.74 | AO30: 0.72 | AP30: 0.68 | AQ30: 0.62 | AR30: 0.6 | AS30: 0.53 | AT30: 0.53 | AU30: 0.54 | AV30: 0.6 | AW30: 0.6 | AX30: 0.49 | AY30: 0.48 | AZ30: 0.44 | BA30: 0.43 | BB30: 0.42 | BC30: 0.42 | BD30: 0.42 | BE30: 0.4 | BF30: 0.39 | BG30: 0.39 | BH30: 0.39 | BI30: 0.39 | BJ30: 0.39 | BK30: 0.39 | BL30: 0.39 | BM30: 0.39 | BN30: 0.37 | BO30: 0.37 | BP30: 0.36 | BQ30: 0.36 | BR30: 0.35 | BS30: 0.35 | BT30: 0.35 | BU30: 0.32 | BV30: 0.32 | BW30: 0.32 | BX30: 0.32 | BY30: 0.32 | BZ30: 0.32 | CA30: 0.32 | CB30: 0.32 | CC30: 0.32 | CD30: 0.32 | CE30: 0.32 | CF30: 0.32 | CG30: 0.32 | CH30: 0.32 | CI30: 0.32 | CJ30: 0.32 | CK30: 0.32 | CL30: 0.32 | CM30: 0.31 | CN30: 0.29 | CO30: 0.29 | CP30: 0.29 | CQ30: 0.29 | CR30: 0.29 | CS30: 0.29 | CT30: 0.28 | CU30: 0.28 | CV30: 0.28 | CW30: 0.28 | CX30: 0.28 | CY30: 0.28 | CZ30: 0.28 | DA30: 0.28 | DB30: 0.28 | DC30: 0.28 | DD30: 0.28 | DE30: 0.28 | DF30: 0.28 | DG30: 0.28 | DH30: 0.28 | DI30: 0.28 | DJ30: 0.28 | DK30: 0.28 | DL30: 0.28 | DM30: 0.28 | DN30: 0.28 | DO30: 0.28 | DP30: 0.28 | DQ30: 0.28 | DR30: 0.28 | DS30: 0.28 | DT30: 0.28 | DU30: 0.28 | DV30: 0.28 | DW30: 0.28 | DX30: 0.28 | DY30: 0.28 | DZ30: 0.28 | EA30: 0.28 | EB30: 0.28
A31: C10 | B31: 双面Topcon电池片（＞24.3%） | C31: 182mm x 183.75mm | D31: 元/瓦 | E31: 0.89 | F31: 0.92 | G31: 0.98 | H31: 1.03 | I31: 1.2 | J31: 1.2 | K31: 1.18 | L31: 1.15 | M31: 1.15 | N31: 1.21 | O31: 1.22 | P31: 1.22 | Q31: 1.22 | R31: 1.22 | S31: 1.22 | T31: 1.22 | U31: 1.22 | V31: 1.18 | W31: 1.12 | X31: 1.1 | Y31: 0.99 | Z31: 0.96 | AA31: 0.88 | AB31: 0.83 | AC31: 0.8 | AD31: 0.81 | AE31: 0.79 | AF31: 0.79 | AG31: 0.79 | AH31: 0.8 | AI31: 0.8 | AJ31: 0.81 | AK31: 0.81 | AL31: 0.81 | AM31: 0.81 | AN31: 0.81 | AO31: 0.74 | AP31: 0.68 | AQ31: 0.68 | AR31: 0.6 | AS31: 0.58 | AT31: 0.53 | AU31: 0.5 | AV31: 0.5 | AW31: 0.5 | AX31: 0.49 | AY31: 0.49 | AZ31: 0.49 | BA31: 0.48 | BB31: 0.48 | BC31: 0.48 | BD31: 0.48 | BE31: 0.48 | BF31: 0.48 | BG31: 0.48 | BH31: 0.48 | BI31: 0.48 | BJ31: 0.485 | BK31: 0.48 | BL31: 0.48 | BM31: 0.48 | BN31: 0.47 | BO31: 0.46 | BP31: 0.42 | BQ31: 0.42 | BR31: 0.395 | BS31: 0.375 | BT31: 0.34 | BU31: 0.31 | BV31: 0.3 | BW31: 0.3 | BX31: 0.3 | BY31: 0.3 | BZ31: 0.3 | CA31: 0.3 | CB31: 0.3 | CC31: 0.29 | CD31: 0.29 | CE31: 0.29 | CF31: 0.29 | CG31: 0.29 | CH31: 0.29 | CI31: 0.29 | CJ31: 0.285 | CK31: 0.28 | CL31: 0.28 | CM31: 0.27 | CN31: 0.27 | CO31: 0.27 | CP31: 0.27 | CQ31: 0.27 | CR31: 0.27 | CS31: 0.27 | CT31: 0.27 | CU31: 0.275 | CV31: 0.28 | CW31: 0.28 | CX31: 0.28 | CY31: 0.28 | CZ31: 0.285 | DA31: 0.285 | DB31: 0.29 | DC31: 0.29 | DD31: 0.29 | DE31: 0.29 | DF31: 0.295 | DG31: 0.295 | DH31: 0.295 | DI31: 0.298 | DJ31: 0.298 | DK31: 0.3 | DL31: 0.3 | DM31: 0.3 | DN31: 0.3 | DO31: 0.3 | DP31: 0.295 | DQ31: 0.28 | DR31: 0.28 | DS31: 0.268 | DT31: 0.265 | DU31: 0.265 | DV31: 0.26 | DW31: 0.255 | DX31: 0.255 | DY31: 0.255 | DZ31: 0.255 | EA31: 0.24 | EB31: 0.235 | EC31: 0.225 | ED31: 0.23 | EE31: 0.25 | EF31: 0.28 | EG31: 0.305 | EH31: 0.315 | EI31: 0.295 | EJ31: 0.295 | EK31: 0.298 | EL31: 0.298 | EM31: 0.305 | EN31: 0.315 | EO31: 0.325 | EP31: 0.325 | EQ31: 0.325 | ER31: 0.325 | ES31: 0.325 | ET31: 0.31 | EU31: 0.31 | EV31: 0.308 | EW31: 0.295 | EX31: 0.292 | EY31: 0.285 | EZ31: 0.295 | FA31: 0.32 | FB31: 0.32 | FC31: 0.37 | FD31: 0.38 | FE31: 0.41 | FF31: 0.435 | FG31: 0.435 | FH31: 0.435 | FI31: 0.435 | FJ31: 0.42 | FK31: 0.42 | FL31: 0.4 | FM31: 0.38 | FN31: 0.37 | FO31: 0.35 | FP31: 0.345 | FQ31: 0.325 | FR31: 0.325 | FS31: 0.325 | FT31: 0.325 | FU31: 0.325 | FV31: 0.325 | FW31: 0.325 | FX31: 0.31 | FY31: 0.31 | FZ31: 0.285 | GA31: 0.27 | GB31: 0.268 | GC31: 0.265 | GD31: 0.265 | GE31: 0.265 | GF31: 0.275 | GG31: 0.3 | GH31: 0.38 | GI31: 0.335 | GJ31: 0.31 | GK31: 0.31 | GL31: 0.3
A32: C11 | B32: 双面Topcon电池片（＞24.3%）（New！） | C32: 210mm x 210mm | D32: 元/瓦 | BX32: 0.36 | BY32: 0.35 | BZ32: 0.35 | CA32: 0.35 | CB32: 0.35 | CC32: 0.33 | CD32: 0.33 | CE32: 0.32 | CF32: 0.32 | CG32: 0.32 | CH32: 0.32 | CI32: 0.32 | CJ32: 0.3 | CK32: 0.29 | CL32: 0.29 | CM32: 0.285 | CN32: 0.29 | CO32: 0.29 | CP32: 0.29 | CQ32: 0.29 | CR32: 0.29 | CS32: 0.29 | CT32: 0.285 | CU32: 0.285 | CV32: 0.285 | CW32: 0.285 | CX32: 0.285 | CY32: 0.285 | CZ32: 0.285 | DA32: 0.29 | DB32: 0.29 | DC32: 0.29 | DD32: 0.29 | DE32: 0.29 | DF32: 0.295 | DG32: 0.295 | DH32: 0.295 | DI32: 0.295 | DJ32: 0.295 | DK32: 0.305 | DL32: 0.305 | DM32: 0.305 | DN32: 0.305 | DO32: 0.305 | DP32: 0.3 | DQ32: 0.29 | DR32: 0.29 | DS32: 0.28 | DT32: 0.28 | DU32: 0.28 | DV32: 0.28 | DW32: 0.27 | DX32: 0.27 | DY32: 0.27 | DZ32: 0.27 | EA32: 0.26 | EB32: 0.255 | EC32: 0.245 | ED32: 0.245 | EE32: 0.255 | EF32: 0.275 | EG32: 0.29 | EH32: 0.29 | EI32: 0.285 | EJ32: 0.285 | EK32: 0.288 | EL32: 0.288 | EM32: 0.29 | EN32: 0.3 | EO32: 0.3 | EP32: 0.3 | EQ32: 0.3 | ER32: 0.31 | ES32: 0.31 | ET32: 0.3 | EU32: 0.3 | EV32: 0.298 | EW32: 0.288 | EX32: 0.285 | EY32: 0.283 | EZ32: 0.295 | FA32: 0.32 | FB32: 0.32 | FC32: 0.38 | FD32: 0.38 | FE32: 0.41 | FF32: 0.435 | FG32: 0.435 | FH32: 0.435 | FI32: 0.435 | FJ32: 0.422 | FK32: 0.422 | FL32: 0.4 | FM32: 0.39 | FN32: 0.37 | FO32: 0.36 | FP32: 0.354 | FQ32: 0.34 | FR32: 0.34 | FS32: 0.34 | FT32: 0.34 | FU32: 0.34 | FV32: 0.33 | FW32: 0.33 | FX32: 0.315 | FY32: 0.315 | FZ32: 0.295 | GA32: 0.275 | GB32: 0.272 | GC32: 0.27 | GD32: 0.27 | GE32: 0.27 | GF32: 0.27 | GG32: 0.295 | GH32: 0.36 | GI32: 0.31 | GJ32: 0.31 | GK32: 0.31 | GL32: 0.295
A33: D10 | B33: 多晶组件 | C33: 270-275W | D33: 元/瓦
A34: D9 | B34: 多晶双玻组件 | C34: 270-275W | D34: 元/瓦
A35: D4 | B35: 单晶PERC组件 | C35: 320-330W / 390-410W | D35: 元/瓦 | E35: 1.75 | F35: 1.72 | G35: 1.72 | H35: 1.72 | I35: 1.72 | J35: 1.72 | K35: 1.72 | L35: 1.72 | M35: 1.72
A36: D5 | B36: 单晶PERC组件 | C36: 355-365W / 430-440W | D36: 元/瓦 | E36: 1.82 | F36: 1.75 | G36: 1.75 | H36: 1.75 | I36: 1.75 | J36: 1.75 | K36: 1.75 | L36: 1.75 | M36: 1.75
A37: D14 | B37: 单面单晶perc组件（182系列） | C37: 530-540W（72片） | D37: 元/瓦 | E37: 1.83 | F37: 1.79 | G37: 1.79 | H37: 1.79 | I37: 1.79 | J37: 1.78 | K37: 1.78 | L37: 1.76 | M37: 1.76 | N37: 1.76 | O37: 1.74 | P37: 1.73 | Q37: 1.73 | R37: 1.73 | S37: 1.73 | T37: 1.71 | U37: 1.71 | V37: 1.68 | W37: 1.62 | X37: 1.62 | Y37: 1.6 | Z37: 1.57 | AA37: 1.4 | AB37: 1.38 | AC37: 1.375 | AD37: 1.36 | AE37: 1.33 | AF37: 1.31 | AG37: 1.31 | AH37: 1.27 | AI37: 1.27 | AJ37: 1.27 | AK37: 1.27 | AL37: 1.27 | AM37: 1.27 | AN37: 1.255 | AO37: 1.22 | AP37: 1.16 | AQ37: 1.13 | AR37: 1.1 | AS37: 1.08 | AT37: 1.02 | AU37: 1 | AV37: 1 | AW37: 0.98 | AX37: 0.98 | AY37: 0.93 | AZ37: 0.92 | BA37: 0.88 | BB37: 0.87 | BC37: 0.87 | BD37: 0.87 | BE37: 0.86 | BF37: 0.86 | BG37: 0.86 | BH37: 0.86 | BI37: 0.86 | BJ37: 0.86 | BK37: 0.86 | BL37: 0.86 | BM37: 0.86 | BN37: 0.85 | BO37: 0.85 | BP37: 0.85 | BQ37: 0.85 | BR37: 0.84 | BS37: 0.83 | BT37: 0.82 | BU37: 0.8 | BV37: 0.8 | BW37: 0.8 | BX37: 0.8 | BY37: 0.78 | BZ37: 0.78 | CA37: 0.75 | CB37: 0.74 | CC37: 0.74 | CD37: 0.74 | CE37: 0.74 | CF37: 0.74 | CG37: 0.74 | CH37: 0.74 | CI37: 0.74 | CJ37: 0.74 | CK37: 0.74 | CL37: 0.74 | CM37: 0.72 | CN37: 0.68 | CO37: 0.68 | CP37: 0.68 | CQ37: 0.68 | CR37: 0.68 | CS37: 0.68 | CT37: 0.68 | CU37: 0.67 | CV37: 0.67 | CW37: 0.67 | CX37: 0.67 | CY37: 0.67 | CZ37: 0.67 | DA37: 0.65 | DB37: 0.65 | DC37: 0.65 | DD37: 0.65 | DE37: 0.65 | DF37: 0.65 | DG37: 0.65 | DH37: 0.65 | DI37: 0.65 | DJ37: 0.65 | DK37: 0.65 | DL37: 0.65 | DM37: 0.65 | DN37: 0.65 | DO37: 0.65 | DP37: 0.65 | DQ37: 0.65 | DR37: 0.65 | DS37: 0.65 | DT37: 0.65 | DU37: 0.65 | DV37: 0.65 | DW37: 0.65 | DX37: 0.65 | DY37: 0.65 | DZ37: 0.65 | EA37: 0.65 | EB37: 0.65 | EC37: 0.65 | ED37: 0.65 | EE37: 0.65 | EF37: 0.65 | EG37: 0.65 | EH37: 0.65 | EI37: 0.65 | EJ37: 0.65 | EK37: 0.65 | EL37: 0.65 | EM37: 0.65 | EN37: 0.65
A38: D7 | B38: 双面单晶perc组件（182系列） | C38: 530-540W（72片） | D38: 元/瓦 | E38: 1.85 | F38: 1.81 | G38: 1.81 | H38: 1.81 | I38: 1.81 | J38: 1.8 | K38: 1.8 | L38: 1.78 | M38: 1.78 | N38: 1.78 | O38: 1.76 | P38: 1.75 | Q38: 1.75 | R38: 1.75 | S38: 1.75 | T38: 1.73 | U38: 1.73 | V38: 1.7 | W38: 1.65 | X38: 1.65 | Y38: 1.62 | Z38: 1.59 | AA38: 1.42 | AB38: 1.4 | AC38: 1.395 | AD38: 1.39 | AE38: 1.355 | AF38: 1.33 | AG38: 1.33 | AH38: 1.28 | AI38: 1.28 | AJ38: 1.28 | AK38: 1.28 | AL38: 1.28 | AM38: 1.28 | AN38: 1.265 | AO38: 1.24 | AP38: 1.18 | AQ38: 1.15 | AR38: 1.12 | AS38: 1.1 | AT38: 1.05 | AU38: 1.04 | AV38: 1.04 | AW38: 1.03 | AX38: 1.03 | AY38: 0.95 | AZ38: 0.94 | BA38: 0.92 | BB38: 0.91 | BC38: 0.91 | BD38: 0.91 | BE38: 0.89 | BF38: 0.89 | BG38: 0.89 | BH38: 0.89 | BI38: 0.89 | BJ38: 0.89 | BK38: 0.89 | BL38: 0.89 | BM38: 0.89 | BN38: 0.88 | BO38: 0.88 | BP38: 0.88 | BQ38: 0.88 | BR38: 0.87 | BS38: 0.86 | BT38: 0.85 | BU38: 0.82 | BV38: 0.82 | BW38: 0.82 | BX38: 0.82 | BY38: 0.8 | BZ38: 0.8 | CA38: 0.8 | CB38: 0.78 | CC38: 0.78 | CD38: 0.78 | CE38: 0.78 | CF38: 0.78 | CG38: 0.78 | CH38: 0.78 | CI38: 0.78 | CJ38: 0.78 | CK38: 0.76 | CL38: 0.76 | CM38: 0.74 | CN38: 0.71 | CO38: 0.71 | CP38: 0.71 | CQ38: 0.69 | CR38: 0.68 | CS38: 0.68 | CT38: 0.68 | CU38: 0.67 | CV38: 0.67 | CW38: 0.67 | CX38: 0.67 | CY38: 0.67 | CZ38: 0.67 | DA38: 0.665 | DB38: 0.665 | DC38: 0.665 | DD38: 0.665 | DE38: 0.665 | DF38: 0.665 | DG38: 0.665 | DH38: 0.665 | DI38: 0.665 | DJ38: 0.665 | DK38: 0.665 | DL38: 0.665 | DM38: 0.665 | DN38: 0.665 | DO38: 0.665 | DP38: 0.665 | DQ38: 0.665 | DR38: 0.665 | DS38: 0.665 | DT38: 0.665 | DU38: 0.665 | DV38: 0.665 | DW38: 0.665 | DX38: 0.665 | DY38: 0.665 | DZ38: 0.665 | EA38: 0.665 | EB38: 0.665 | EC38: 0.665 | ED38: 0.665 | EE38: 0.665 | EF38: 0.665 | EG38: 0.665 | EH38: 0.665 | EI38: 0.665 | EJ38: 0.665 | EK38: 0.665 | EL38: 0.665 | EM38: 0.665 | EN38: 0.665
A39: D8 | B39: 双面单晶perc组件（210系列） | C39: 540-550W（50片） | D39: 元/瓦 | E39: 1.85 | F39: 1.81 | G39: 1.81 | H39: 1.81 | I39: 1.81 | J39: 1.8 | K39: 1.8 | L39: 1.78 | M39: 1.78 | N39: 1.78 | O39: 1.76 | P39: 1.75 | Q39: 1.75 | R39: 1.75 | S39: 1.75 | T39: 1.73 | U39: 1.73 | V39: 1.7 | W39: 1.66 | X39: 1.66 | Y39: 1.63 | Z39: 1.61 | AA39: 1.44 | AB39: 1.42 | AC39: 1.415 | AD39: 1.41 | AE39: 1.36 | AF39: 1.33 | AG39: 1.33 | AH39: 1.28 | AI39: 1.28 | AJ39: 1.28 | AK39: 1.28 | AL39: 1.28 | AM39: 1.28 | AN39: 1.265 | AO39: 1.24 | AP39: 1.18 | AQ39: 1.15 | AR39: 1.14 | AS39: 1.12 | AT39: 1.05 | AU39: 1.04 | AV39: 1.13 | AW39: 1.13 | AX39: 1.13 | AY39: 0.98 | AZ39: 0.96 | BA39: 0.94 | BB39: 0.93 | BC39: 0.93 | BD39: 0.93 | BE39: 0.92 | BF39: 0.92 | BG39: 0.92 | BH39: 0.92 | BI39: 0.92 | BJ39: 0.92 | BK39: 0.92 | BL39: 0.92 | BM39: 0.92 | BN39: 0.9 | BO39: 0.9 | BP39: 0.9 | BQ39: 0.9 | BR39: 0.88 | BS39: 0.87 | BT39: 0.86 | BU39: 0.83 | BV39: 0.83 | BW39: 0.83 | BX39: 0.83 | BY39: 0.82 | BZ39: 0.82 | CA39: 0.82 | CB39: 0.8 | CC39: 0.8 | CD39: 0.8 | CE39: 0.79 | CF39: 0.79 | CG39: 0.79 | CH39: 0.79 | CI39: 0.79 | CJ39: 0.79 | CK39: 0.78 | CL39: 0.78 | CM39: 0.75 | CN39: 0.72 | CO39: 0.72 | CP39: 0.72 | CQ39: 0.7 | CR39: 0.69 | CS39: 0.69 | CT39: 0.69 | CU39: 0.68 | CV39: 0.68 | CW39: 0.68 | CX39: 0.68 | CY39: 0.68 | CZ39: 0.68 | DA39: 0.67 | DB39: 0.67 | DC39: 0.67 | DD39: 0.67 | DE39: 0.67 | DF39: 0.67 | DG39: 0.67 | DH39: 0.67 | DI39: 0.67 | DJ39: 0.67 | DK39: 0.67 | DL39: 0.67 | DM39: 0.67 | DN39: 0.67 | DO39: 0.67 | DP39: 0.67 | DQ39: 0.67 | DR39: 0.67 | DS39: 0.67 | DT39: 0.67 | DU39: 0.67 | DV39: 0.67 | DW39: 0.67 | DX39: 0.67 | DY39: 0.67 | DZ39: 0.67 | EA39: 0.67 | EB39: 0.67 | EC39: 0.67 | ED39: 0.67 | EE39: 0.67 | EF39: 0.67 | EG39: 0.67 | EH39: 0.67 | EI39: 0.67 | EJ39: 0.67 | EK39: 0.67 | EL39: 0.67 | EM39: 0.67 | EN39: 0.67
A40: D15 | B40: 双面Topcon组件（182系列） | C40: 550-570W（72片） | D40: 元/瓦 | E40: 1.92 | F40: 1.87 | G40: 1.87 | H40: 1.87 | I40: 1.87 | J40: 1.87 | K40: 1.85 | L40: 1.85 | M40: 1.85 | N40: 1.85 | O40: 1.85 | P40: 1.85 | Q40: 1.85 | R40: 1.85 | S40: 1.85 | T40: 1.83 | U40: 1.83 | V40: 1.78 | W40: 1.74 | X40: 1.74 | Y40: 1.7 | Z40: 1.69 | AA40: 1.5 | AB40: 1.48 | AC40: 1.455 | AD40: 1.455 | AE40: 1.397 | AF40: 1.38 | AG40: 1.38 | AH40: 1.33 | AI40: 1.33 | AJ40: 1.33 | AK40: 1.33 | AL40: 1.33 | AM40: 1.33 | AN40: 1.33 | AO40: 1.28 | AP40: 1.24 | AQ40: 1.18 | AR40: 1.17 | AS40: 1.15 | AT40: 1.13 | AU40: 1.1 | AV40: 1.1 | AW40: 1.09 | AX40: 1.09 | AY40: 1.03 | AZ40: 1.03 | BA40: 1.02 | BB40: 1.02 | BC40: 1.02 | BD40: 1.02 | BE40: 1.02 | BF40: 0.96 | BG40: 0.96 | BH40: 0.96 | BI40: 0.96 | BJ40: 0.96 | BK40: 0.96 | BL40: 0.96 | BM40: 0.96 | BN40: 0.96 | BO40: 0.96 | BP40: 0.96 | BQ40: 0.96 | BR40: 0.94 | BS40: 0.92 | BT40: 0.9 | BU40: 0.88 | BV40: 0.86 | BW40: 0.86 | BX40: 0.86 | BY40: 0.83 | BZ40: 0.81 | CA40: 0.81 | CB40: 0.81 | CC40: 0.8 | CD40: 0.8 | CE40: 0.8 | CF40: 0.8 | CG40: 0.78 | CH40: 0.775 | CI40: 0.775 | CJ40: 0.75 | CK40: 0.75 | CL40: 0.75 | CM40: 0.75 | CN40: 0.74 | CO40: 0.74 | CP40: 0.72 | CQ40: 0.72 | CR40: 0.72 | CS40: 0.72 | CT40: 0.7 | CU40: 0.7 | CV40: 0.7 | CW40: 0.7 | CX40: 0.7 | CY40: 0.7 | CZ40: 0.7 | DA40: 0.7 | DB40: 0.7 | DC40: 0.7 | DD40: 0.69 | DE40: 0.69 | DF40: 0.69 | DG40: 0.69 | DH40: 0.69 | DI40: 0.69 | DJ40: 0.71 | DK40: 0.72 | DL40: 0.75 | DM40: 0.75 | DN40: 0.75 | DO40: 0.75 | DP40: 0.73 | DQ40: 0.73 | DR40: 0.715 | DS40: 0.705 | DT40: 0.685 | DU40: 0.685 | DV40: 0.685 | DW40: 0.68 | DX40: 0.68 | DY40: 0.68 | DZ40: 0.68 | EA40: 0.68 | EB40: 0.67 | EC40: 0.67 | ED40: 0.67 | EE40: 0.675 | EF40: 0.7 | EG40: 0.7 | EH40: 0.7 | EI40: 0.7 | EJ40: 0.7 | EK40: 0.7 | EL40: 0.7 | EM40: 0.7 | EN40: 0.7 | EO40: 0.69 | EP40: 0.69 | EQ40: 0.69 | ER40: 0.69 | ES40: 0.69 | ET40: 0.69 | EU40: 0.69 | EV40: 0.69 | EW40: 0.69 | EX40: 0.68 | EY40: 0.68 | EZ40: 0.68 | FA40: 0.68 | FB40: 0.68 | FC40: 0.685 | FD40: 0.708 | FE40: 0.74 | FF40: 0.8 | FG40: 0.8 | FH40: 0.8 | FI40: 0.83 | FJ40: 0.83 | FK40: 0.82 | FL40: 0.81 | FM40: 0.81 | FN40: 0.78 | FO40: 0.76 | FP40: 0.76 | FQ40: 0.758 | FR40: 0.758 | FS40: 0.758 | FT40: 0.758 | FU40: 0.75 | FV40: 0.75 | FW40: 0.75 | FX40: 0.74 | FY40: 0.74 | FZ40: 0.72 | GA40: 0.71 | GB40: 0.7 | GC40: 0.68 | GD40: 0.66 | GE40: 0.655 | GF40: 0.645 | GG40: 0.645 | GH40: 0.65 | GI40: 0.66
...

Sheet Sheet1
A3: Year | B3: 2023 | C3: 2023 | D3: 2023 | E3: 2023 | F3: 2023 | G3: 2023 | H3: 2023 | I3: 2023 | J3: 2023 | K3: 2023 | L3: 2023 | M3: 2023 | N3: 2023 | O3: 2023 | P3: 2023 | Q3: 2023 | R3: 2023 | S3: 2023 | T3: 2023 | U3: 2023 | V3: 2023 | W3: 2023 | X3: 2023 | Y3: 2023 | Z3: 2023 | AA3: 2023 | AB3: 2023 | AC3: 2023 | AD3: 2023 | AE3: 2023 | AF3: 2023 | AG3: 2023 | AH3: 2023 | AI3: 2023 | AJ3: 2023 | AK3: 2023 | AL3: 2023 | AM3: 2023 | AN3: 2023 | AO3: 2023 | AP3: 2023 | AQ3: 2023 | AR3: 2023 | AS3: 2023 | AT3: 2023 | AU3: 2023 | AV3: 2023 | AW3: 2023 | AX3: 2023 | AY3: 2023 | AZ3: 2023 | BA3: 2024 | BB3: 2024 | BC3: 2024 | BD3: 2024 | BE3: 2024 | BF3: 2024 | BG3: 2024 | BH3: 2024 | BI3: 2024 | BJ3: 2024 | BK3: 2024 | BL3: 2024 | BM3: 2024 | BN3: 2024 | BO3: 2024 | BP3: 2024 | BQ3: 2024 | BR3: 2024 | BS3: 2024 | BT3: 2024 | BU3: 2024 | BV3: 2024 | BW3: 2024 | BX3: 2024 | BY3: 2024 | BZ3: 2024 | CA3: 2024 | CB3: 2024 | CC3: 2024 | CD3: 2024 | CE3: 2024 | CF3: 2024 | CG3: 2024 | CH3: 2024 | CI3: 2024 | CJ3: 2024 | CK3: 2024 | CL3: 2024 | CM3: 2024 | CN3: 2024 | CO3: 2024 | CP3: 2024 | CQ3: 2024 | CR3: 2024 | CS3: 2024 | CT3: 2024 | CU3: 2024 | CV3: 2024 | CW3: 2024 | CX3: 2025 | CY3: 2025 | CZ3: 2025 | DA3: 2025 | DB3: 2025 | DC3: 2025 | DD3: 2025 | DE3: 2025 | DF3: 2025 | DG3: 2025 | DH3: 2025 | DI3: 2025 | DJ3: 2025 | DK3: 2025 | DL3: 2025 | DM3: 2025 | DN3: 2025 | DO3: 2025 | DP3: 2025 | DQ3: 2025 | DR3: 2025 | DS3: 2025 | DT3: 2025 | DU3: 2025 | DV3: 2025 | DW3: 2025 | DX3: 2025 | DY3: 2025 | DZ3: 2025 | EA3: 2025 | EB3: 2025 | EC3: 2025 | ED3: 2025 | EE3: 2025 | EF3: 2025 | EG3: 2025 | EH3: 2025 | EI3: 2025 | EJ3: 2025 | EK3: 2025 | EL3: 2025 | EM3: 2025 | EN3: 2025 | EO3: 2025 | EP3: 2025 | EQ3: 2025 | ER3: 2025 | ES3: 2025 | ET3: 2025 | EU3: 2025 | EV3: 2025 | EW3: 2026 | EX3: 2026 | EY3: 2026 | EZ3: 2026 | FA3: 2026 | FB3: 2026 | FC3: 2026 | FD3: 2026 | FE3: 2026 | FF3: 2026 | FG3: 2026 | FH3: 2026 | FI3: 2026 | FJ3: 2026 | FK3: 2026 | FL3: 2026 | FM3: 2026 | FN3: 2026 | FO3: 2026 | FP3: 2026 | FQ3: 2026 | FR3: 2026 | FS3: 2026 | FT3: 2026 | FU3: 2026 | FV3: 2026 | FW3: 2026 | FX3: 2026 | FY3: 2026 | FZ3: 2026 | GA3: 2026 | GB3: 2026 | GC3: 2026 | GD3: 2026 | GE3: 2026 | GF3: 2026 | GG3: 2026 | GH3: 2026 | GI3: 2026
A4: Week | B4: 1 | C4: 2 | D4: 3 | E4: 5 | F4: 6 | G4: 7 | H4: 8 | I4: 9 | J4: 10 | K4: 11 | L4: 12 | M4: 13 | N4: 14 | O4: 15 | P4: 16 | Q4: 17 | R4: 18 | S4: 19 | T4: 20 | U4: 21 | V4: 22 | W4: 23 | X4: 24 | Y4: 25 | Z4: 26 | AA4: 27 | AB4: 28 | AC4: 29 | AD4: 30 | AE4: 31 | AF4: 32 | AG4: 33 | AH4: 34 | AI4: 35 | AJ4: 36 | AK4: 37 | AL4: 38 | AM4: 39 | AN4: 40 | AO4: 41 | AP4: 42 | AQ4: 43 | AR4: 44 | AS4: 45 | AT4: 46 | AU4: 47 | AV4: 48 | AW4: 49 | AX4: 50 | AY4: 51 | AZ4: 52 | BA4: 1 | BB4: 2 | BC4: 3 | BD4: 4 | BE4: 5 | BF4: 6 | BG4: 8 | BH4: 9 | BI4: 10 | BJ4: 11 | BK4: 12 | BL4: 13 | BM4: 14 | BN4: 15 | BO4: 16 | BP4: 17 | BQ4: 19 | BR4: 20 | BS4: 21 | BT4: 22 | BU4: 23 | BV4: 24 | BW4: 25 | BX4: 26 | BY4: 27 | BZ4: 28 | CA4: 29 | CB4: 30 | CC4: 31 | CD4: 32 | CE4: 33 | CF4: 34 | CG4: 35 | CH4: 36 | CI4: 37 | CJ4: 38 | CK4: 39 | CL4: 41 | CM4: 42 | CN4: 43 | CO4: 44 | CP4: 45 | CQ4: 46 | CR4: 47 | CS4: 48 | CT4: 49 | CU4: 50 | CV4: 51 | CW4: 52 | CX4: 1 | CY4: 2 | CZ4: 3 | DA4: 4 | DB4: 6 | DC4: 7 | DD4: 8 | DE4: 9 | DF4: 10 | DG4: 11 | DH4: 12 | DI4: 13 | DJ4: 14 | DK4: 15 | DL4: 16 | DM4: 17 | DN4: 18 | DO4: 19 | DP4: 20 | DQ4: 21 | DR4: 22 | DS4: 23 | DT4: 24 | DU4: 25 | DV4: 26 | DW4: 27 | DX4: 28 | DY4: 29 | DZ4: 30 | EA4: 31 | EB4: 32 | EC4: 33 | ED4: 34 | EE4: 35 | EF4: 36 | EG4: 37 | EH4: 38 | EI4: 39 | EJ4: 41 | EK4: 42 | EL4: 43 | EM4: 44 | EN4: 45 | EO4: 46 | EP4: 47 | EQ4: 48 | ER4: 49 | ES4: 50 | ET4: 51 | EU4: 52 | EV4: EoY | EW4: 1 | EX4: 2 | EY4: 3 | EZ4: 4 | FA4: 5 | FB4: 6 | FC4: 8 | FD4: 9 | FE4: 10 | FF4: 11 | FG4: 12 | FH4: 13 | FI4: 14 | FJ4: 15 | FK4: 16 | FL4: 17 | FM4: 18 | FN4: 19 | FO4: 20 | FP4: 21 | FQ4: 22 | FR4: 23 | FS4: 24 | FT4: 25 | FU4: 26 | FV4: 27 | FW4: 28 | FX4: 29 | FY4: 30 | FZ4: 31 | GA4: 32 | GB4: 33 | GC4: 34 | GD4: 35 | GE4: 36 | GF4: 37 | GG4: WoW (%) | GH4: MoM (%) | GI4: YtD (%)
A5: Polysilicon RMB/kg (USD/kg)
A6: N-Type Silicon in China | AB6: 74.5 | AC6: 76 | AD6: 76.3 | AE6: 80 | AF6: 80.2 | AG6: 84 | AH6: 86 | AI6: 90 | AJ6: 92 | AK6: 92 | AL6: 92 | AM6: 92 | AN6: 92 | AO6: 92 | AP6: 85 | AQ6: 75 | AR6: 72 | AS6: 69 | AT6: 68.5 | AU6: 68 | AV6: 67 | AW6: 67 | AX6: 67 | AY6: =Sheet2!BB50 -> 67 | AZ6: =Sheet2!BC50 -> 67 | BA6: =Sheet2!BD50 -> 67 | BB6: =Sheet2!BE50 -> 69.5 | BC6: =Sheet2!BF50 -> 69.5 | BD6: =Sheet2!BG50 -> 69.5 | BE6: =Sheet2!BH50 -> 69.5 | BF6: =Sheet2!BI50 -> 69.5 | ... DH6: =Sheet2!DK50 -> 42 | DI6: 42 | DJ6: =Sheet2!DN50 -> 42 | DK6: =Sheet2!DO50 -> 42 | DL6: =Sheet2!DP50 -> 42 | DM6: =Sheet2!DQ50 -> 39.5 | DN6: =Sheet2!DR50 -> 39.5 | DO6: =Sheet2!DS50 -> 39.5 | DP6: 39.5 | DQ6: =Sheet2!DV50 -> 38.5 | DR6: =Sheet2!DW50 -> 36.5 | DS6: 36.5 | DT6: =Sheet2!DZ50 -> 36.5 | DU6: =Sheet2!EA50 -> 35.5 | DV6: =Sheet2!EB50 -> 35.5 | DW6: =Sheet2!EC50 -> 35.5 | DX6: =Sheet2!ED50 -> 36 | DY6: =Sheet2!EE50 -> 46 | DZ6: =Sheet2!EF50 -> 46 | EA6: =Sheet2!EG50 -> 48 | ... GF6: =Sheet2!GL50 -> 43 | GG6: =((100*GF6)/GE6-100) -> 0 | GH6: =((SUM(GC6:GF6)-SUM(FY6:GB6))/SUM(FY6:GB6))*100 -> 16.153846 | GI6: =100*GF6/EW6-100 -> -18.095238
A7: Reusable Chinese 9N | B7: 210 | C7: 170 | D7: 170 | E7: 208 | F7: 240 | G7: 241 | H7: 241 | I7: 240 | J7: 228 | K7: 220 | L7: 215 | M7: 209 | N7: 201 | O7: 196 | P7: 194 | Q7: 182 | R7: 181 | S7: 161 | T7: 140 | U7: 135 | V7: 120 | W7: 115 | X7: 65 | Y7: 64.8 | Z7: 64 | AA7: 64 | AB7: 64.5 | AC7: 66 | AD7: 68 | AE7: 70.5 | AF7: 71.5 | AG7: 73.5 | AH7: 75 | AI7: 80 | AJ7: 82 | AK7: 82 | AL7: 82 | AM7: 82 | AN7: 82 | AO7: 80 | AP7: 75 | AQ7: 70 | AR7: 65 | AS7: 63.5 | AT7: 63 | AU7: 63 | AV7: 62.5 | AW7: 62.5 | AX7: 61 | AY7: =Sheet2!BB2 -> 61 | AZ7: =Sheet2!BC2 -> 61 | BA7: =Sheet2!BD2 -> 61 | BB7: =Sheet2!BE2 -> 61.5 | BC7: =Sheet2!BF2 -> 61.5 | BD7: =Sheet2!BG2 -> 61.5 | BE7: =Sheet2!BH2 -> 61.5 | BF7: =Sheet2!BI2 -> 61.5 | ... DH7: =Sheet2!DK2 -> 35 | DI7: 35 | DJ7: =Sheet2!DN2 -> 35 | DK7: =Sheet2!DO2 -> 35 | DL7: =Sheet2!DP2 -> 35 | DM7: =Sheet2!DQ2 -> 35 | DN7: =Sheet2!DR2 -> 35 | DO7: =Sheet2!DS2 -> 35 | DP7: 35 | DQ7: =Sheet2!DV2 -> 35 | DR7: =Sheet2!DW2 -> 35 | DS7: 35 | DT7: =Sheet2!DZ2 -> 35 | DU7: =Sheet2!EA2 -> 33.5 | DV7: =Sheet2!EB2 -> 33.5 | DW7: =Sheet2!EC2 -> 33.5 | DX7: =Sheet2!ED2 -> 33.5 | DY7: =Sheet2!EE2 -> 43 | DZ7: =Sheet2!EF2 -> 43 | EA7: =Sheet2!EG2 -> 43 | ... GF7: =Sheet2!GL2 -> 38 | GG7: =((100*GF7)/GE7-100) -> 0 | GH7: =((SUM(GC7:GF7)-SUM(FY7:GB7))/SUM(FY7:GB7))*100 -> 13.333333 | GI7: =100*GF7/EW7-100 -> -12.643678
A8: Chinese 9N | B8: 200 | C8: 162 | D8: 162 | E8: 200 | F8: 237 | G8: 237 | H8: 237 | I8: 234 | J8: 223 | K8: 218 | L8: 212 | M8: 206 | N8: 199 | O8: 194 | P8: 192 | Q8: 180 | R8: 178 | S8: 155 | T8: 138 | U8: 132 | V8: 115 | W8: 110 | X8: 63 | Y8: 62.5 | Z8: 62 | AA8: 62 | AB8: 62 | AC8: 64 | AD8: 65 | AE8: 68 | AF8: 69 | AG8: 71.5 | AH8: 73 | AI8: 77 | AJ8: 77 | AK8: 77 | AL8: 77 | AM8: 77 | AN8: 77 | AO8: 77 | AP8: 72 | AQ8: 65 | AR8: 65 | AS8: 65 | AT8: 65 | AU8: 64 | AV8: 60 | AW8: 60 | AX8: 59.5 | AY8: =Sheet2!BB3 -> 59.5 | AZ8: =Sheet2!BC3 -> 59.5 | BA8: =Sheet2!BD3 -> 59.5 | BB8: =Sheet2!BE3 -> 59.5 | BC8: =Sheet2!BF3 -> 59.5 | BD8: =Sheet2!BG3 -> 59.5 | BE8: =Sheet2!BH3 -> 59.5 | BF8: =Sheet2!BI3 -> 59.5 | ... DH8: =Sheet2!DK3 -> 34 | DI8: 34 | DJ8: =Sheet2!DN3 -> 34 | DK8: =Sheet2!DO3 -> 34 | DL8: =Sheet2!DP3 -> 34 | DM8: =Sheet2!DQ3 -> 34 | DN8: =Sheet2!DR3 -> 34 | DO8: =Sheet2!DS3 -> 34 | DP8: 34 | DQ8: =Sheet2!DV3 -> 34 | DR8: =Sheet2!DW3 -> 34 | DS8: 34 | DT8: =Sheet2!DZ3 -> 34 | DU8: =Sheet2!EA3 -> 32.5 | DV8: =Sheet2!EB3 -> 32.5 | DW8: =Sheet2!EC3 -> 32.5 | DX8: =Sheet2!ED3 -> 32.5 | DY8: =Sheet2!EE3 -> 42 | DZ8: =Sheet2!EF3 -> 42 | EA8: =Sheet2!EG3 -> 42 | ... GF8: =Sheet2!GL3 -> 36 | GG8: =((100*GF8)/GE8-100) -> 0 | GH8: =((SUM(GC8:GF8)-SUM(FY8:GB8))/SUM(FY8:GB8))*100 -> 14.285714 | GI8: =100*GF8/EW8-100 -> -15.294118
A9: Granular silicon | AJ9: 75 | AK9: 75 | AL9: 80 | AM9: 80 | AN9: 78 | AO9: 78 | AP9: 0 | AQ9: 0 | AR9: 62 | AS9: 62 | AT9: 62 | AU9: 62 | AV9: 61 | AW9: 61 | AX9: 61 | AY9: =Sheet2!BB51 -> 61 | AZ9: =Sheet2!BC51 -> 61 | BA9: =Sheet2!BD51 -> 61 | BB9: =Sheet2!BE51 -> 61 | BC9: =Sheet2!BF51 -> 61 | BD9: =Sheet2!BG51 -> 61 | BE9: =Sheet2!BH51 -> 61 | BF9: =Sheet2!BI51 -> 61 | ... DH9: =Sheet2!DK51 -> 39 | DI9: 39 | DJ9: =Sheet2!DN51 -> 39 | DK9: =Sheet2!DO51 -> 39 | DL9: =Sheet2!DP51 -> 39 | DM9: =Sheet2!DQ51 -> 37.5 | DN9: =Sheet2!DR51 -> 37.5 | DO9: =Sheet2!DS51 -> 36.5 | DP9: 35.5 | DQ9: =Sheet2!DV51 -> 35.5 | DR9: =Sheet2!DW51 -> 35.5 | DS9: 35.5 | DT9: =Sheet2!DZ51 -> 35.5 | DU9: =Sheet2!EA51 -> 34 | DV9: =Sheet2!EB51 -> 34 | DW9: =Sheet2!EC51 -> 36 | DX9: =Sheet2!ED51 -> 34 | DY9: =Sheet2!EE51 -> 44 | DZ9: =Sheet2!EF51 -> 44 | EA9: =Sheet2!EG51 -> 45 | ... GF9: =Sheet2!GL51 -> 41 | GG9: =((100*GF9)/GE9-100) -> 0 | GH9: =((SUM(GC9:GF9)-SUM(FY9:GB9))/SUM(FY9:GB9))*100 -> 15.079365 | GI9: =100*GF9/EW9-100 -> -18
A10: Global (USD/kg) | B10: 30 | C10: 28 | D10: 28 | E10: 28 | F10: 35 | G10: 35 | H10: 35 | I10: 35 | J10: 33 | K10: 33 | L10: 33 | M10: 33 | N10: 31 | O10: 30 | P10: 29 | Q10: 27 | R10: 26 | S10: 23.5 | T10: 23 | U10: 22.8 | V10: 21.5 | W10: 21 | X10: 20 | Y10: 20 | Z10: 20 | AA10: 20 | AB10: 20 | AC10: 20 | AD10: 20 | AE10: 20 | AF10: 20 | AG10: 20 | AH10: 20 | AI10: 20 | AJ10: 20 | AK10: 20 | AL10: 20 | AM10: 20 | AN10: 20 | AO10: 20 | AP10: 20 | AQ10: 20 | AR10: 20 | AS10: 20 | AT10: 20 | AU10: 20 | AV10: 20 | AW10: 20 | AX10: 20 | AY10: =Sheet2!BB5 -> 20 | AZ10: =Sheet2!BC5 -> 20 | BA10: =Sheet2!BD5 -> 20 | BB10: =Sheet2!BE5 -> 20 | BC10: =Sheet2!BF5 -> 20 | BD10: =Sheet2!BG5 -> 20 | BE10: =Sheet2!BH5 -> 20 | BF10: =Sheet2!BI5 -> 20 | ... DH10: =Sheet2!DK5 -> 20 | DI10: 20 | DJ10: =Sheet2!DN5 -> 20 | DK10: =Sheet2!DO5 -> 20 | DL10: =Sheet2!DP5 -> 20 | DM10: =Sheet2!DQ5 -> 20 | DN10: =Sheet2!DR5 -> 20 | DO10: =Sheet2!DS5 -> 20 | DP10: 20 | DQ10: =Sheet2!DV5 -> 20 | DR10: =Sheet2!DW5 -> 20 | DS10: 20 | DT10: =Sheet2!DZ5 -> 20 | DU10: =Sheet2!EA5 -> 20 | DV10: =Sheet2!EB5 -> 20 | DW10: =Sheet2!EC5 -> 20 | DX10: =Sheet2!ED5 -> 20 | DY10: =Sheet2!EE5 -> 20 | DZ10: =Sheet2!EF5 -> 20 | EA10: =Sheet2!EG5 -> 20 | ... FH10: =Sheet2!FN5 -> 20 | GI10: =100*GF10/EW10-100 -> -100
A11: Wafer RMB/piece
A12: p-type, 182 mm, 150 µm（下线） | B12: 3.5 | C12: 3.6 | D12: 4.5 | E12: 4.8 | F12: 6.22 | G12: 6.22 | H12: 6.22 | I12: 6.22 | J12: 6.4 | K12: 6.5 | L12: 6.4 | M12: 6.4 | N12: 6.4 | O12: 6.4 | P12: 6.38 | Q12: 6.3 | R12: 5.84 | S12: 5.4 | T12: 4.6 | U12: 4.4 | V12: 4 | W12: 3.6 | X12: 2.8 | Y12: 2.8 | Z12: 2.8 | AA12: 2.75 | AB12: 2.78 | AC12: 2.78 | AD12: 2.9 | AE12: 2.95 | AF12: 2.95 | AG12: 3.15 | AH12: 3.35 | AI12: 3.35 | AJ12: 3.35 | AK12: 3.35 | AL12: 3.35 | AM12: 3.08 | AN12: 2.8 | AO12: 2.75 | AP12: 2.55 | AQ12: 2.4 | AR12: 2.4 | AS12: 2.4 | AT12: 2.35 | AU12: 2.3 | AV12: 2.12 | AW12: 2.12 | AX12: 2.05 | AY12: =Sheet2!BB18 -> 2 | AZ12: =Sheet2!BC18 -> 2 | BA12: =Sheet2!BD18 -> 2 | BB12: =Sheet2!BE18 -> 2 | BC12: =Sheet2!BF18 -> 2.02 | BD12: =Sheet2!BG18 -> 2.02 | BE12: =Sheet2!BH18 -> 2.02 | BF12: =Sheet2!BI18 -> 2.02 | ... DH12: =Sheet2!DK18 -> 1.08 | DI12: 1.08 | DK12: - | DL12: - | DM12: - | EX12: -
A13: p-type 210 mm, 150 µm（下线） | B13: 4.8 | C13: 4.8 | D13: 6.2 | E13: 6.2 | F13: 8.2 | G13: 8.2 | H13: 8.2 | I13: 8.2 | J13: 8.2 | K13: 8.2 | L13: 8.2 | M13: 8.2 | N13: 8.05 | O13: 8.05 | P13: 8.05 | Q13: 8.05 | R13: 7.6 | S13: 7.4 | T13: 6 | U13: 5.8 | V13: 5.1 | W13: 5 | X13: 4 | Y13: 4 | Z13: 4 | AA13: 4 | AB13: 3.77 | AC13: 3.77 | AD13: 3.77 | AE13: 3.92 | AF13: 3.92 | AG13: 4.1 | AH13: 4.35 | AI13: 4.35 | AJ13: 4.35 | AK13: 4.25 | AL13: 4.2 | AM13: 4.02 | AN13: 3.9 | AO13: 3.66 | AP13: 3.45 | AQ13: 3.3 | AR13: 3.3 | AS13: 3.3 | AT13: 3.3 | AU13: 3.3 | AV13: 3.3 | AW13: 3.05 | AX13: 3 | AY13: =Sheet2!BB23 -> 3 | AZ13: =Sheet2!BC23 -> 3 | BA13: =Sheet2!BD23 -> 3 | BB13: =Sheet2!BE23 -> 2.95 | BC13: =Sheet2!BF23 -> 2.95 | BD13: =Sheet2!BG23 -> 2.85 | BE13: =Sheet2!BH23 -> 2.8 | BF13: =Sheet2!BI23 -> 2.8 | ... DH13: =Sheet2!DK23 -> 1.65 | DI13: 1.58 | DK13: - | DL13: - | DM13: - | EX13: -
A14: n-type 210 mm, 150 µm | B14: 6.3 | C14: 5.1 | D14: 5.3 | E14: 5.3 | EX14: -
A15: n-type 210 mm, 130 µm | F15: 8.52 | G15: 8.52 | H15: 8.52 | I15: 8.52 | J15: 8.52 | K15: 8.52 | L15: 8.52 | M15: 8.52 | N15: 8.2 | O15: 8.2 | P15: 8.2 | Q15: 8.2 | R15: 7.74 | S15: 7.6 | T15: 6.8 | U15: 6.7 | V15: 6.2 | W15: 6.1 | X15: 5 | Y15: 5 | Z15: 5 | AA15: 5 | AB15: 3.84 | AC15: 3.84 | AD15: 3.84 | AE15: 3.98 | AF15: 3.98 | AG15: 4.25 | AH15: 4.32 | AI15: 4.32 | AJ15: 4.32 | AK15: 4.32 | AL15: 4.32 | AM15: 4.2 | AN15: 3.95 | AO15: 3.85 | AP15: 3.5 | AQ15: 3.35 | AR15: 3.35 | AS15: 3.35 | AT15: 3.35 | AU15: 3.35 | AV15: 3.35 | AW15: 3.35 | AX15: 3.25 | AY15: =Sheet2!BB49 -> 3.23 | AZ15: =Sheet2!BC49 -> 3.23 | BA15: =Sheet2!BD49 -> 3.23 | BB15: =Sheet2!BE49 -> 3.1 | BC15: =Sheet2!BF49 -> 3.1 | BD15: =Sheet2!BG49 -> 3.08 | BE15: =Sheet2!BH49 -> 3.08 | BF15: =Sheet2!BI49 -> 3.08 | ... DH15: =Sheet2!DK49 -> 1.55 | DI15: 1.55 | DJ15: =Sheet2!DN49 -> 1.58 | DK15: =Sheet2!DO49 -> 1.58 | DL15: =Sheet2!DP49 -> 1.55 | DM15: =Sheet2!DQ49 -> 1.45 | DN15: =Sheet2!DR49 -> 1.45 | DO15: =Sheet2!DS49 -> 1.35 | DP15: 1.3 | DQ15: =Sheet2!DV49 -> 1.3 | DR15: =Sheet2!DW49 -> 1.3 | DS15: 1.3 | DT15: =Sheet2!DZ49 -> 1.3 | DU15: =Sheet2!EA49 -> 1.25 | DV15: =Sheet2!EB49 -> 1.23 | DW15: =Sheet2!EC49 -> 1.23 | DX15: =Sheet2!ED49 -> 1.3 | DY15: =Sheet2!EE49 -> 1.4 | DZ15: =Sheet2!EF49 -> 1.45 | EA15: =Sheet2!EG49 -> 1.55 | ... GF15: =Sheet2!GL49 -> 1.15 | GG15: =((100*GF15)/GE15-100) -> -4.1666667 | GH15: =((SUM(GC15:GF15)-SUM(FY15:GB15))/SUM(FY15:GB15))*100 -> 6.6666667 | GI15: =100*GF15/EW15-100 -> -25.806452
A16: n-type 182 mm, 130 µm | F16: 6.52 | G16: 6.52 | H16: 6.52 | I16: 6.52 | J16: 6.52 | K16: 6.52 | L16: 6.52 | M16: 6.52 | N16: 6.52 | O16: 6.52 | P16: 6.52 | Q16: 6.52 | R16: 5.95 | S16: 5.8 | T16: 5 | U16: 4.9 | V16: 4.5 | W16: 4.15 | X16: 3.5 | Y16: 3.5 | Z16: 3.5 | AA16: 3.5 | AB16: 2.9 | AC16: 2.9 | AD16: 2.9 | AE16: 3.01 | AF16: 3.01 | AG16: 3.2 | AH16: 3.26 | AI16: 3.26 | AJ16: 3.26 | AK16: 3.26 | AL16: 3.26 | AM16: 3.2 | AN16: 3.05 | AO16: 2.9 | AP16: 2.7 | AQ16: 2.55 | AR16: 2.55 | AS16: 2.55 | AT16: 2.55 | AU16: 2.55 | AV16: 2.55 | AW16: 2.55 | AX16: 2.4 | AY16: =Sheet2!BB48 -> 2.3 | AZ16: =Sheet2!BC48 -> 2.3 | BA16: =Sheet2!BD48 -> 2.3 | BB16: =Sheet2!BE48 -> 2.3 | BC16: =Sheet2!BF48 -> 2.2 | BD16: =Sheet2!BG48 -> 2.15 | BE16: =Sheet2!BH48 -> 2.15 | BF16: =Sheet2!BI48 -> 2.15 | ... DH16: =Sheet2!DK48 -> 1.2 | DI16: 1.23 | DJ16: =Sheet2!DN48 -> 1.28 | DK16: =Sheet2!DO48 -> 1.28 | DL16: =Sheet2!DP48 -> 1.28 | DM16: =Sheet2!DQ48 -> 1.15 | DN16: =Sheet2!DR48 -> 1.15 | DO16: =Sheet2!DS48 -> 1.02 | DP16: 0.98 | DQ16: =Sheet2!DV48 -> 0.98 | DR16: =Sheet2!DW48 -> 0.98 | DS16: 0.98 | DT16: =Sheet2!DZ48 -> 0.98 | DU16: =Sheet2!EA48 -> 0.9 | DV16: =Sheet2!EB48 -> 0.86 | DW16: =Sheet2!EC48 -> 0.86 | DX16: =Sheet2!ED48 -> 0.95 | DY16: =Sheet2!EE48 -> 1.05 | DZ16: =Sheet2!EF48 -> 1.1 | EA16: =Sheet2!EG48 -> 1.2 | ... GF16: =Sheet2!GL48 -> 1.02 | GG16: =((100*GF16)/GE16-100) -> -5.5555556 | GH16: =((SUM(GC16:GF16)-SUM(FY16:GB16))/SUM(FY16:GB16))*100 -> 30.909091 | GI16: =100*GF16/EW16-100 -> -18.4
A17: N type wafer-210Rmm(130um) | CI17: =Sheet2!CL54 -> 1.3 | CJ17: =Sheet2!CM54 -> 1.25 | CK17: =Sheet2!CN54 -> 1.3 | CL17: =Sheet2!CO54 -> 1.3 | CM17: =Sheet2!CP54 -> 1.25 | CN17: =Sheet2!CQ54 -> 1.25 | CO17: =Sheet2!CR54 -> 1.25 | CP17: =Sheet2!CS54 -> 1.2 | ... DH17: =Sheet2!DK54 -> 1.4 | DI17: 1.45 | DJ17: =Sheet2!DN54 -> 1.55 | DK17: =Sheet2!DO54 -> 1.53 | DL17: =Sheet2!DP54 -> 1.5 | DM17: =Sheet2!DQ54 -> 1.3 | DN17: =Sheet2!DR54 -> 1.3 | DO17: =Sheet2!DS54 -> 1.15 | DP17: 1.1 | DQ17: =Sheet2!DV54 -> 1.09 | DR17: =Sheet2!DW54 -> 1.08 | DS17: 1.08 | DT17: =Sheet2!DZ54 -> 1.08 | DU17: =Sheet2!EA54 -> 1.03 | DV17: =Sheet2!EB54 -> 1.025 | DW17: =Sheet2!EC54 -> 1.025 | DX17: =Sheet2!ED54 -> 1.1 | DY17: =Sheet2!EE54 -> 1.2 | DZ17: =Sheet2!EF54 -> 1.25 | EA17: =Sheet2!EG54 -> 1.35 | ... GF17: =Sheet2!GL54 -> 1.05 | GG17: =((100*GF17)/GE17-100) -> -2.7777778 | GH17: =((SUM(GC17:GF17)-SUM(FY17:GB17))/SUM(FY17:GB17))*100 -> 18.378378 | GI17: =100*GF17/EW17-100 -> -22.222222
A18: Cells RMB/W
A19: PERC bifacial - p-type, 182 mm(下线） | B19: 0.8 | C19: 0.83 | D19: 0.92 | E19: 0.97 | F19: 1.14 | G19: 1.14 | H19: 1.13 | I19: 1.09 | J19: 1.09 | K19: 1.1 | L19: 1.09 | M19: 1.1 | N19: 1.1 | O19: 1.1 | P19: 1.1 | Q19: 1.1 | R19: 1.09 | S19: 1.04 | T19: 1 | U19: 0.96 | V19: 0.88 | W19: 0.86 | X19: 0.79 | Y19: 0.72 | Z19: 0.71 | AA19: 0.715 | AB19: 0.73 | AC19: 0.735 | AD19: 0.745 | AE19: 0.75 | AF19: 0.755 | AG19: 0.76 | AH19: 0.76 | AI19: 0.76 | AJ19: 0.76 | AK19: 0.75 | AL19: 0.71 | AM19: 0.65 | AN19: 0.61 | AO19: 0.55 | AP19: 0.51 | AQ19: 0.48 | AR19: 0.46 | AS19: 0.46 | AT19: 0.46 | AU19: 0.45 | AV19: 0.43 | AW19: 0.425 | AX19: 0.39 | AY19: =Sheet2!BB29 -> 0.36 | AZ19: =Sheet2!BC29 -> 0.36 | BA19: =Sheet2!BD29 -> 0.39 | BB19: =Sheet2!BE29 -> 0.39 | BC19: =Sheet2!BF29 -> 0.39 | BD19: =Sheet2!BG29 -> 0.39 | BE19: =Sheet2!BH29 -> 0.39 | BF19: =Sheet2!BI29 -> 0.39 | ... DH19: =Sheet2!DK29 -> 0.275 | DI19: 0.275 | DJ19: =Sheet2!DN29 -> 0.275 | DK19: =Sheet2!DO29 -> 0.275 | DL19: =Sheet2!DP29 -> 0.275 | DM19: =Sheet2!DQ29 -> 0.275 | DN19: =Sheet2!DR29 -> 0.275 | DO19: =Sheet2!DS29 -> 0.275 | DP19: 0.27 | DQ19: =Sheet2!DV29 -> 0.27 | DR19: =Sheet2!DW29 -> 0.27 | DS19: 0.27 | DT19: =Sheet2!DZ29 -> 0.27 | DU19: =Sheet2!EA29 -> 0.27 | DV19: =Sheet2!EB29 -> 0.27 | EX19: -
A20: PERC bifacial - p-type, 210 mm(下线） | B20: 0.8 | C20: 0.83 | D20: 0.92 | E20: 0.97 | F20: 1.14 | G20: 1.14 | H20: 1.13 | I20: 1.1 | J20: 1.1 | K20: 1.1 | L20: 1.1 | M20: 1.13 | N20: 1.13 | O20: 1.13 | P20: 1.13 | Q20: 1.13 | R20: 1.13 | S20: 1.1 | T20: 1.06 | U20: 1.02 | V20: 0.9 | W20: 0.9 | X20: 0.83 | Y20: 0.75 | Z20: 0.74 | AA20: 0.74 | AB20: 0.73 | AC20: 0.73 | AD20: 0.73 | AE20: 0.74 | AF20: 0.74 | AG20: 0.74 | AH20: 0.74 | AI20: 0.74 | AJ20: 0.74 | AK20: 0.74 | AL20: 0.72 | AM20: 0.68 | AN20: 0.62 | AO20: 0.6 | AP20: 0.53 | AQ20: 0.53 | AR20: 0.54 | AS20: 0.6 | AT20: 0.6 | AU20: 0.49 | AV20: 0.48 | AW20: 0.44 | AX20: 0.43 | AY20: =Sheet2!BB30 -> 0.42 | AZ20: =Sheet2!BC30 -> 0.42 | BA20: =Sheet2!BD30 -> 0.42 | BB20: =Sheet2!BE30 -> 0.4 | BC20: =Sheet2!BF30 -> 0.39 | BD20: =Sheet2!BG30 -> 0.39 | BE20: =Sheet2!BH30 -> 0.39 | BF20: =Sheet2!BI30 -> 0.39 | ... DH20: =Sheet2!DK30 -> 0.28 | DI20: 0.28 | DJ20: =Sheet2!DN30 -> 0.28 | DK20: =Sheet2!DO30 -> 0.28 | DL20: =Sheet2!DP30 -> 0.28 | DM20: =Sheet2!DQ30 -> 0.28 | DN20: =Sheet2!DR30 -> 0.28 | DO20: =Sheet2!DS30 -> 0.28 | DP20: 0.28 | DQ20: =Sheet2!DV30 -> 0.28 | DR20: =Sheet2!DW30 -> 0.28 | DS20: 0.28 | DT20: =Sheet2!DZ30 -> 0.28 | DU20: =Sheet2!EA30 -> 0.28 | DV20: =Sheet2!EB30 -> 0.28 | EX20: -
A21: TOPCon - n-type, 182 mm | B21: 0.89 | C21: 0.92 | D21: 0.98 | E21: 1.03 | F21: 1.2 | G21: 1.2 | H21: 1.18 | I21: 1.15 | J21: 1.15 | K21: 1.21 | L21: 1.22 | M21: 1.22 | N21: 1.22 | O21: 1.22 | P21: 1.22 | Q21: 1.22 | R21: 1.22 | S21: 1.18 | T21: 1.12 | U21: 1.1 | V21: 0.99 | W21: 0.96 | X21: 0.88 | Y21: 0.83 | Z21: 0.8 | AA21: 0.81 | AB21: 0.79 | AC21: 0.79 | AD21: 0.79 | AE21: 0.8 | AF21: 0.8 | AG21: 0.81 | AH21: 0.81 | AI21: 0.81 | AJ21: 0.81 | AK21: 0.81 | AL21: 0.74 | AM21: 0.68 | AN21: 0.68 | AO21: 0.6 | AP21: 0.58 | AQ21: 0.53 | AR21: 0.5 | AS21: 0.5 | AT21: 0.5 | AU21: 0.49 | AV21: 0.49 | AW21: 0.49 | AX21: 0.48 | AY21: =Sheet2!BB31 -> 0.48 | AZ21: =Sheet2!BC31 -> 0.48 | BA21: =Sheet2!BD31 -> 0.48 | BB21: =Sheet2!BE31 -> 0.48 | BC21: =Sheet2!BF31 -> 0.48 | BD21: =Sheet2!BG31 -> 0.48 | BE21: =Sheet2!BH31 -> 0.48 | BF21: =Sheet2!BI31 -> 0.48 | ... DH21: =Sheet2!DK31 -> 0.3 | DI21: 0.3 | DJ21: =Sheet2!DN31 -> 0.3 | DK21: =Sheet2!DO31 -> 0.3 | DL21: =Sheet2!DP31 -> 0.295 | DM21: =Sheet2!DQ31 -> 0.28 | DN21: =Sheet2!DR31 -> 0.28 | DO21: =Sheet2!DS31 -> 0.268 | DP21: 0.265 | DQ21: =Sheet2!DV31 -> 0.26 | DR21: =Sheet2!DW31 -> 0.255 | DS21: 0.255 | DT21: =Sheet2!DZ31 -> 0.255 | DU21: =Sheet2!EA31 -> 0.24 | DV21: =Sheet2!EB31 -> 0.235 | DW21: =Sheet2!EC31 -> 0.225 | DX21: =Sheet2!ED31 -> 0.23 | DY21: =Sheet2!EE31 -> 0.25 | DZ21: =Sheet2!EF31 -> 0.28 | EA21: =Sheet2!EG31 -> 0.305 | ... GF21: =Sheet2!GL31 -> 0.3 | GG21: =((100*GF21)/GE21-100) -> -3.2258065 | GH21: =((SUM(GC21:GF21)-SUM(FY21:GB21))/SUM(FY21:GB21))*100 -> 2.8688525 | GI21: =100*GF21/EW21-100 -> -18.918919
A22: TOPCon - n-type, 210 mm | AV22: - | AW22: - | AX22: - | AY22: - | AZ22: - | BA22: - | BB22: - | BC22: - | BD22: - | BE22: - | BF22: - | BG22: - | BH22: - | BI22: - | BJ22: - | BK22: - | BL22: - | BM22: - | BN22: - | BO22: - | BP22: - | BQ22: - | BR22: - | BS22: - | BT22: - | BU22: =Sheet2!BX32 -> 0.36 | BV22: =Sheet2!BY32 -> 0.35 | BW22: =Sheet2!BZ32 -> 0.35 | BX22: =Sheet2!CA32 -> 0.35 | BY22: =Sheet2!CB32 -> 0.35 | BZ22: =Sheet2!CC32 -> 0.33 | CA22: =Sheet2!CD32 -> 0.33 | CB22: =Sheet2!CE32 -> 0.32 | ... DH22: =Sheet2!DK32 -> 0.305 | DI22: 0.305 | DJ22: =Sheet2!DN32 -> 0.305 | DK22: =Sheet2!DO32 -> 0.305 | DL22: =Sheet2!DP32 -> 0.3 | DM22: =Sheet2!DQ32 -> 0.29 | DN22: =Sheet2!DR32 -> 0.29 | DO22: =Sheet2!DS32 -> 0.28 | DP22: 0.28 | DQ22: =Sheet2!DV32 -> 0.28 | DR22: =Sheet2!DW32 -> 0.27 | DS22: 0.27 | DT22: =Sheet2!DZ32 -> 0.27 | DU22: =Sheet2!EA32 -> 0.26 | DV22: =Sheet2!EB32 -> 0.255 | DW22: =Sheet2!EC32 -> 0.245 | DX22: =Sheet2!ED32 -> 0.245 | DY22: =Sheet2!EE32 -> 0.255 | DZ22: =Sheet2!EF32 -> 0.275 | EA22: =Sheet2!EG32 -> 0.29 | ... GF22: =Sheet2!GL32 -> 0.295 | GG22: =((100*GF22)/GE22-100) -> -4.8387097 | GH22: =((SUM(GC22:GF22)-SUM(FY22:GB22))/SUM(FY22:GB22))*100 -> 2.5104603 | GI22: =100*GF22/EW22-100 -> -22.368421
A23: Bifacial 210Rmm Topcon cell(above 24.3% ) | CI23: =Sheet2!CL55 -> 0.29 | CJ23: =Sheet2!CM55 -> 0.28 | CK23: =Sheet2!CN55 -> 0.285 | CL23: =Sheet2!CO55 -> 0.285 | CM23: =Sheet2!CP55 -> 0.285 | CN23: =Sheet2!CQ55 -> 0.285 | CO23: =Sheet2!CR55 -> 0.285 | CP23: =Sheet2!CS55 -> 0.285 | ... DH23: =Sheet2!DK55 -> 0.35 | DI23: 0.34 | DJ23: =Sheet2!DN55 -> 0.34 | DK23: =Sheet2!DO55 -> 0.33 | DL23: =Sheet2!DP55 -> 0.295 | DM23: =Sheet2!DQ55 -> 0.28 | DN23: =Sheet2!DR55 -> 0.28 | DO23: =Sheet2!DS55 -> 0.268 | DP23: 0.265 | DQ23: =Sheet2!DV55 -> 0.26 | DR23: =Sheet2!DW55 -> 0.26 | DS23: 0.26 | DT23: =Sheet2!DZ55 -> 0.26 | DU23: =Sheet2!EA55 -> 0.26 | DV23: =Sheet2!EB55 -> 0.255 | DW23: =Sheet2!EC55 -> 0.245 | DX23: =Sheet2!ED55 -> 0.245 | DY23: =Sheet2!EE55 -> 0.262 | DZ23: =Sheet2!EF55 -> 0.275 | EA23: =Sheet2!EG55 -> 0.29 | ... GF23: =Sheet2!GL55 -> 0.315 | GG23: =((100*GF23)/GE23-100) -> 5 | GH23: =((SUM(GC23:GF23)-SUM(FY23:GB23))/SUM(FY23:GB23))*100 -> 1.1608624 | GI23: =100*GF23/EW23-100 -> -14.864865
A24: Modules RMB/W
A25: PERC monofacial - p-type, 182 mm (540-550W)/(420-495W) | B25: 1.83 | C25: 1.79 | D25: 1.79 | E25: 1.79 | F25: 1.79 | G25: 1.78 | H25: 1.78 | I25: 1.76 | J25: 1.76 | K25: 1.76 | L25: 1.74 | M25: 1.73 | N25: 1.73 | O25: 1.73 | P25: 1.73 | Q25: 1.71 | R25: 1.71 | S25: 1.68 | T25: 1.62 | U25: 1.62 | V25: 1.6 | W25: 1.57 | X25: 1.4 | Y25: 1.38 | Z25: 1.375 | AA25: 1.36 | AB25: 1.33 | AC25: 1.31 | AD25: 1.31 | AE25: 1.27 | AF25: 1.27 | AG25: 1.27 | AH25: 1.27 | AI25: 1.27 | AJ25: 1.27 | AK25: 1.255 | AL25: 1.22 | AM25: 1.16 | AN25: 1.13 | AO25: 1.1 | AP25: 1.08 | AQ25: 1.02 | AR25: 1 | AS25: 1 | AT25: 0.98 | AU25: 0.98 | AV25: 0.93 | AW25: 0.92 | AX25: 0.88 | AY25: =Sheet2!BB37 -> 0.87 | AZ25: =Sheet2!BC37 -> 0.87 | BA25: =Sheet2!BD37 -> 0.87 | BB25: =Sheet2!BE37 -> 0.86 | BC25: =Sheet2!BF37 -> 0.86 | BD25: =Sheet2!BG37 -> 0.86 | BE25: =Sheet2!BH37 -> 0.86 | BF25: =Sheet2!BI37 -> 0.86 | ... DH25: =Sheet2!DK37 -> 0.65 | DI25: 0.65 | DJ25: =Sheet2!DN37 -> 0.65 | DK25: =Sheet2!DO37 -> 0.65 | DL25: =Sheet2!DP37 -> 0.65 | DM25: =Sheet2!DQ37 -> 0.65 | DN25: =Sheet2!DR37 -> 0.65 | DO25: =Sheet2!DS37 -> 0.65 | DP25: 0.65 | DQ25: =Sheet2!DV37 -> 0.65 | DR25: =Sheet2!DW37 -> 0.65 | DS25: 0.65 | DT25: =Sheet2!DZ37 -> 0.65 | DU25: =Sheet2!EA37 -> 0.65 | DV25: =Sheet2!EB37 -> 0.65 | DW25: =Sheet2!EC37 -> 0.65 | DX25: =Sheet2!ED37 -> 0.65 | DY25: =Sheet2!EE37 -> 0.65 | DZ25: =Sheet2!EF37 -> 0.65 | EA25: =Sheet2!EG37 -> 0.65 | ... EH25: =Sheet2!EN37 -> 0.65 | EX25: -
A26: PERC bifacial - p-type, 182 mm, 72 cells (540-550W)/(420-495W) | B26: 1.85 | C26: 1.81 | D26: 1.81 | E26: 1.81 | F26: 1.81 | G26: 1.8 | H26: 1.8 | I26: 1.78 | J26: 1.78 | K26: 1.78 | L26: 1.76 | M26: 1.75 | N26: 1.75 | O26: 1.75 | P26: 1.75 | Q26: 1.73 | R26: 1.73 | S26: 1.7 | T26: 1.65 | U26: 1.65 | V26: 1.62 | W26: 1.59 | X26: 1.42 | Y26: 1.4 | Z26: 1.395 | AA26: 1.39 | AB26: 1.355 | AC26: 1.33 | AD26: 1.33 | AE26: 1.28 | AF26: 1.28 | AG26: 1.28 | AH26: 1.28 | AI26: 1.28 | AJ26: 1.28 | AK26: 1.265 | AL26: 1.24 | AM26: 1.18 | AN26: 1.15 | AO26: 1.12 | AP26: 1.1 | AQ26: 1.05 | AR26: 1.04 | AS26: 1.04 | AT26: 1.03 | AU26: 1.03 | AV26: 0.95 | AW26: 0.94 | AX26: 0.92 | AY26: =Sheet2!BB38 -> 0.91 | AZ26: =Sheet2!BC38 -> 0.91 | BA26: =Sheet2!BD38 -> 0.91 | BB26: =Sheet2!BE38 -> 0.89 | BC26: =Sheet2!BF38 -> 0.89 | BD26: =Sheet2!BG38 -> 0.89 | BE26: =Sheet2!BH38 -> 0.89 | BF26: =Sheet2!BI38 -> 0.89 | ... DH26: =Sheet2!DK38 -> 0.665 | DI26: 0.665 | DJ26: =Sheet2!DN38 -> 0.665 | DK26: =Sheet2!DO38 -> 0.665 | DL26: =Sheet2!DP38 -> 0.665 | DM26: =Sheet2!DQ38 -> 0.665 | DN26: =Sheet2!DR38 -> 0.665 | DO26: =Sheet2!DS38 -> 0.665 | DP26: 0.665 | DQ26: =Sheet2!DV38 -> 0.665 | DR26: =Sheet2!DW38 -> 0.665 | DS26: 0.665 | DT26: =Sheet2!DZ38 -> 0.665 | DU26: =Sheet2!EA38 -> 0.665 | DV26: =Sheet2!EB38 -> 0.665 | DW26: =Sheet2!EC38 -> 0.665 | DX26: =Sheet2!ED38 -> 0.665 | DY26: =Sheet2!EE38 -> 0.665 | DZ26: =Sheet2!EF38 -> 0.665 | EA26: =Sheet2!EG38 -> 0.665 | ... EH26: =Sheet2!EN38 -> 0.665 | EX26: -
A27: PERC bifacial - p-type, 210 mm, 55 cells (540-550W) | B27: 1.85 | C27: 1.81 | D27: 1.81 | E27: 1.81 | F27: 1.81 | G27: 1.8 | H27: 1.8 | I27: 1.78 | J27: 1.78 | K27: 1.78 | L27: 1.76 | M27: 1.75 | N27: 1.75 | O27: 1.75 | P27: 1.75 | Q27: 1.73 | R27: 1.73 | S27: 1.7 | T27: 1.66 | U27: 1.66 | V27: 1.63 | W27: 1.61 | X27: 1.44 | Y27: 1.42 | Z27: 1.415 | AA27: 1.41 | AB27: 1.36 | AC27: 1.33 | AD27: 1.33 | AE27: 1.28 | AF27: 1.28 | AG27: 1.28 | AH27: 1.28 | AI27: 1.28 | AJ27: 1.28 | AK27: 1.265 | AL27: 1.24 | AM27: 1.18 | AN27: 1.15 | AO27: 1.14 | AP27: 1.12 | AQ27: 1.05 | AR27: 1.04 | AS27: 1.13 | AT27: 1.13 | AU27: 1.13 | AV27: 0.98 | AW27: 0.96 | AX27: 0.94 | AY27: =Sheet2!BB39 -> 0.93 | AZ27: =Sheet2!BC39 -> 0.93 | BA27: =Sheet2!BD39 -> 0.93 | BB27: =Sheet2!BE39 -> 0.92 | BC27: =Sheet2!BF39 -> 0.92 | BD27: =Sheet2!BG39 -> 0.92 | BE27: =Sheet2!BH39 -> 0.92 | BF27: =Sheet2!BI39 -> 0.92 | ... DH27: =Sheet2!DK39 -> 0.67 | DI27: 0.67 | DJ27: =Sheet2!DN39 -> 0.67 | DK27: =Sheet2!DO39 -> 0.67 | DL27: =Sheet2!DP39 -> 0.67 | DM27: =Sheet2!DQ39 -> 0.67 | DN27: =Sheet2!DR39 -> 0.67 | DO27: =Sheet2!DS39 -> 0.67 | DP27: 0.67 | DQ27: =Sheet2!DV39 -> 0.67 | DR27: =Sheet2!DW39 -> 0.67 | DS27: 0.67 | DT27: =Sheet2!DZ39 -> 0.67 | DU27: =Sheet2!EA39 -> 0.67 | DV27: =Sheet2!EB39 -> 0.67 | DW27: =Sheet2!EC39 -> 0.67 | DX27: =Sheet2!ED39 -> 0.67 | DY27: =Sheet2!EE39 -> 0.67 | DZ27: =Sheet2!EF39 -> 0.67 | EA27: =Sheet2!EG39 -> 0.67 | ... EH27: =Sheet2!EN39 -> 0.67 | EX27: - | GP27: l
A28: TOPCon bifacial - n-type, 182 mm, 72 cells (580-590W) | B28: 1.92 | C28: 1.87 | D28: 1.87 | E28: 1.87 | F28: 1.87 | G28: 1.87 | H28: 1.85 | I28: 1.85 | J28: 1.85 | K28: 1.85 | L28: 1.85 | M28: 1.85 | N28: 1.85 | O28: 1.85 | P28: 1.85 | Q28: 1.83 | R28: 1.83 | S28: 1.78 | T28: 1.74 | U28: 1.74 | V28: 1.7 | W28: 1.69 | X28: 1.5 | Y28: 1.48 | Z28: 1.455 | AA28: 1.455 | AB28: 1.397 | AC28: 1.38 | AD28: 1.38 | AE28: 1.33 | AF28: 1.33 | AG28: 1.33 | AH28: 1.33 | AI28: 1.33 | AJ28: 1.33 | AK28: 1.33 | AL28: 1.28 | AM28: 1.24 | AN28: 1.18 | AO28: 1.17 | AP28: 1.15 | AQ28: 1.13 | AR28: 1.1 | AS28: 1.1 | AT28: 1.09 | AU28: 1.09 | AV28: 1.03 | AW28: 1.03 | AX28: 1.02 | AY28: =Sheet2!BB40 -> 1.02 | AZ28: =Sheet2!BC40 -> 1.02 | BA28: =Sheet2!BD40 -> 1.02 | BB28: =Sheet2!BE40 -> 1.02 | BC28: =Sheet2!BF40 -> 0.96 | BD28: =Sheet2!BG40 -> 0.96 | BE28: =Sheet2!BH40 -> 0.96 | BF28: =Sheet2!BI40 -> 0.96 | ... DH28: =Sheet2!DK40 -> 0.72 | DI28: 0.75 | DJ28: =Sheet2!DN40 -> 0.75 | DK28: =Sheet2!DO40 -> 0.75 | DL28: =Sheet2!DP40 -> 0.73 | DM28: =Sheet2!DQ40 -> 0.73 | DN28: =Sheet2!DR40 -> 0.715 | DO28: =Sheet2!DS40 -> 0.705 | DP28: 0.685 | DQ28: =Sheet2!DV40 -> 0.685 | DR28: =Sheet2!DW40 -> 0.68 | DS28: 0.68 | DT28: =Sheet2!DZ40 -> 0.68 | DU28: =Sheet2!EA40 -> 0.68 | DV28: =Sheet2!EB40 -> 0.67 | DW28: =Sheet2!EC40 -> 0.67 | DX28: =Sheet2!ED40 -> 0.67 | DY28: =Sheet2!EE40 -> 0.675 | DZ28: =Sheet2!EF40 -> 0.7 | EA28: =Sheet2!EG40 -> 0.7 | ... GC28: =Sheet2!GI40 -> 0.66 | GH28: =((SUM(GC28:GF28)-SUM(FY28:GB28))/SUM(FY28:GB28))*100 -> -74.566474 | GI28: =100*GF28/EW28-100 -> -100
A29: TOPCon bifacial - n-type, 210 mm, 60 cells (620-630W) | BC29: =Sheet2!BF52 -> 0.96 | BD29: =Sheet2!BG52 -> 0.96 | BE29: =Sheet2!BH52 -> 0.96 | BF29: =Sheet2!BI52 -> 0.96 | BG29: =Sheet2!BJ52 -> 0.96 | BH29: =Sheet2!BK52 -> 0.96 | BI29: =Sheet2!BL52 -> 0.96 | BJ29: =Sheet2!BM52 -> 0.96 | ... DH29: =Sheet2!DK52 -> 0.725 | DI29: 0.75 | DJ29: =Sheet2!DN52 -> 0.75 | DK29: =Sheet2!DO52 -> 0.75 | DL29: =Sheet2!DP52 -> 0.72 | DM29: =Sheet2!DQ52 -> 0.72 | DN29: =Sheet2!DR52 -> 0.71 | DO29: =Sheet2!DS52 -> 0.695 | DP29: 0.675 | DQ29: =Sheet2!DV52 -> 0.675 | DR29: =Sheet2!DW52 -> 0.67 | DS29: 0.67 | DT29: =Sheet2!DZ52 -> 0.67 | DU29: =Sheet2!EA52 -> 0.67 | DV29: =Sheet2!EB52 -> 0.67 | DW29: =Sheet2!EC52 -> 0.67 | DX29: =Sheet2!ED52 -> 0.67 | DY29: =Sheet2!EE52 -> 0.678 | DZ29: =Sheet2!EF52 -> 0.7 | EA29: =Sheet2!EG52 -> 0.7 | ... GF29: =Sheet2!GL52 -> 0.705 | GG29: =((100*GF29)/GE29-100) -> 0 | GH29: =((SUM(GC29:GF29)-SUM(FY29:GB29))/SUM(FY29:GB29))*100 -> 2.5454545 | GI29: =100*GF29/EW29-100 -> 2.173913
A30: TOPCon bifacial - n-type, 210 mm, 60 cells (710-735W) | EI30: =Sheet2!EO61 -> 0.7 | EJ30: =Sheet2!EP61 -> 0.688 | EK30: =Sheet2!EQ61 -> 0.7 | EL30: =Sheet2!ER61 -> 0.7 | EM30: =Sheet2!ES61 -> 0.7 | EN30: =Sheet2!ET61 -> 0.7 | EO30: =Sheet2!EU61 -> 0.7 | EP30: =Sheet2!EV61 -> 0.7 | ... GC30: =Sheet2!GI61 -> 0.73 | GH30: =((SUM(GC30:GF30)-SUM(FY30:GB30))/SUM(FY30:GB30))*100 -> -74.652778 | GI30: =100*GF30/EW30-100 -> -100
A31: 210mm HJT Module (615-635W) | BG31: =Sheet2!BJ53 -> 1.1 | BH31: =Sheet2!BK53 -> 1.1 | BI31: =Sheet2!BL53 -> 1.1 | BJ31: =Sheet2!BM53 -> 1.1 | BK31: =Sheet2!BN53 -> 1.05 | BL31: =Sheet2!BO53 -> 1.05 | BM31: =Sheet2!BP53 -> 1.05 | BN31: =Sheet2!BQ53 -> 1.05 | ... DH31: =Sheet2!DK53 -> 0.75 | DI31: 0.795 | DJ31: =Sheet2!DN53 -> 0.795 | DK31: =Sheet2!DO53 -> 0.795 | DL31: =Sheet2!DP53 -> 0.76 | DM31: =Sheet2!DQ53 -> 0.76 | DN31: =Sheet2!DR53 -> 0.76 | DO31: =Sheet2!DS53 -> 0.76 | DP31: 0.755 | DQ31: =Sheet2!DV53 -> 0.755 | DR31: =Sheet2!DW53 -> 0.755 | DS31: 0.755 | DT31: =Sheet2!DZ53 -> 0.755 | DU31: =Sheet2!EA53 -> 0.755 | EX31: -
